Workbook

Sheet パルス200w
M2: CODE | AA2: 御 見 積 書
E3: 〒160-8511 | AL3: No. | AN3: FL2602105
D4: 東京都新宿区四谷4-1
AG6: 令和 | AI6: 8 | AL6: 年 | AM6: 2 | AO6: 月 | AP6: 10 | AR6: 日
D7: 大塚刷毛製造株式会社 | T7: 様
D11: 受渡期日 | H11: 相談
D13: 受渡場所 | H13: 貴社住所車上渡し | AB13: 振込先： | AE13: 十六銀行 柳ヶ瀬支店 普通：0777577
D15: 取引方法 | I15: 末締め末払い | AB15: 名義： | AE15: ｶ)ﾘﾝｼｭﾝﾄﾞｳ
E17: 送 料 | G17: 別 | J17: 車上 | N17: 渡し | AB17: 担当者 | AF17: 田中 健吾
J19: =H39 -> 2698410
D20: 税込合計 | J20: =H39 -> 2698410
B22: 見積書有効期限発効後９０日
B24: 品 名 | T24: 数 量 | AA24: 税別単価 | AF24: 金 額 | AM24: 備 考
AF26: =IF(T26="",1*AA26,T26*AA26) -> 0
B27: RSD-SUNMAX-FL-PLC-200w パルスレーザー | X27: 一式 | AA27: 2230000 | AF27: =IF(T27="",1*AA27,T27*AA27) -> 2230000 | AM27: 定価298万円
AF28: =IF(T28="",1*AA28,T28*AA28) -> 0
AF29: =IF(T29="",1*AA29,T29*AA29) -> 0
AF30: =IF(T30="",1*AA30,T30*AA30) -> 0
AF31: =IF(T31="",1*AA31,T31*AA31) -> 0
AF32: =IF(T32="",1*AA32,T32*AA32) -> 0
AF33: =IF(T33="",1*AA33,T33*AA33) -> 0
AF34: =IF(T34="",1*AA34,T34*AA34) -> 0
AF35: =IF(T35="",1*AA35,T35*AA35) -> 0
B36: 出張セットアップ 操作講習 | T36: 1 | X36: 一式 | AA36: 200000 | AF36: =IF(T36="",1*AA36,T36*AA36) -> 200000
B37: 送料 https://www.laser-machine.com/cspt/deli.shtml | T37: 1 | X37: 台 | AA37: 23100 | AF37: =IF(T37="",1*AA37,T37*AA37) -> 23100
B38: 消費税10% | H38: =AA38*0.1 -> 245310 | T38: 小 計 | AA38: =SUM(AF26:AL37) -> 2453100
B39: 合計金額 | H39: =CK115+H38 -> 2698410
B40: 摘要：
B42: 新品1年保証 レンズ類 消耗品除く センドバック修理 送料発送者負担
P56: =SUM(CK115:CQ115) -> 2453100
FB100: NO | FC100: 明細NO | FD100: 品名 | FE100: 数量 | FF100: 単位 | FG100: 単位 | FH100: 金額 | FI100: 備考
FB101: 0 | FC101: 1 | FD101: =B26 -> 0 | FE101: =T26 -> 0 | FF101: =X26 -> 0 | FG101: =AA26 -> 0 | FH101: =AF26 -> 0 | FI101: =AM26 -> 0
EM102: ON | FB102: 0 | FC102: 2 | FD102: =B27 -> RSD-SUNMAX-FL-PLC-200w パルスレーザー | FE102: =T27 -> 0 | FF102: =X27 -> 一式 | FG102: =AA27 -> 2230000 | FH102: =AF27 -> 2230000 | FI102: =AM27 -> 定価298万円
CE103: 制御 | CI103: 総計 | CS103: 単位 | CW103: 消費税 | DD103: タイトル | DM103: ﾏｽﾀﾊﾞｯｸｱｯﾌﾟ | EM103: OFF | FB103: 0 | FC103: 3 | FD103: =B28 -> 0 | FE103: =T28 -> 0 | FF103: =X28 -> 0 | FG103: =AA28 -> 0 | FH103: =AF28 -> 0 | FI103: =AM28 -> 0
CE104: 3 | CI104: 0 | CK104: =AA38 -> 2453100 | CS104: 台 | CW104: 5 | CY104: ％ | DD104: 御 見 積 書 | DM104: ON | FB104: 0 | FC104: 4 | FD104: =B29 -> 0 | FE104: =T29 -> 0 | FF104: =X29 -> 0 | FG104: =AA29 -> 0 | FH104: =AF29 -> 0 | FI104: =AM29 -> 0
CE105: =MAX(FB401:FB642) -> 0 | CI105: 1 | CK105: =IF(ISERROR(購入おすすめ品!AB30),0,購入おすすめ品!AB30) -> 0 | CS105: 個 | DD105: 納 品 書 | FB105: 0 | FC105: 5 | FD105: =#REF! -> #REF! | FE105: =T30 -> 0 | FF105: =X30 -> 0 | FG105: =AA30 -> 0 | FH105: =AF30 -> 0 | FI105: =AM30 -> 0
CE106: 1 | CI106: 2 | CK106: =IF(ISERROR(#REF!),0,#REF!) -> 0 | CS106: 一式 | CV106: 画面表示 | DD106: 納 品 書 （控） | DM106: ﾃﾞｰﾀ保存ｼｰﾄ | FB106: 0 | FC106: 6 | FD106: =#REF! -> #REF! | FE106: =T31 -> 0 | FF106: =X31 -> 0 | FG106: =AA31 -> 0 | FH106: =AF31 -> 0 | FI106: =AM31 -> 0
CE107: 0 | CI107: 3 | CK107: =IF(ISERROR(#REF!),0,#REF!) -> 0 | CS107: 冊 | CV107: ① | CW107: 100 | CZ107: ％ | DD107: 請 求 書 | DM107: データ保存 1.xls | FB107: 0 | FC107: 7 | FD107: =#REF! -> #REF! | FE107: =T32 -> 0 | FF107: =X32 -> 0 | FG107: =AA32 -> 0 | FH107: =AF32 -> 0 | FI107: =AM32 -> 0
CE108: 敬称 | CI108: 4 | CS108: 箱 | CV108: ② | CW108: 80 | CZ108: ％ | DD108: 請 求 書 （控） | DM108: 鑑 | FB108: 0 | FC108: 8 | FD108: =B31 -> 0 | FE108: =T33 -> 0 | FF108: =X33 -> 0 | FG108: =AA33 -> 0 | FH108: =AF33 -> 0 | FI108: =AM33 -> 0
CE109: 御中 | CI109: 5 | CS109: C/S | DM109: 明細 | FB109: 0 | FC109: 9 | FD109: =B34 -> 0 | FE109: =T34 -> 0 | FF109: =X34 -> 0 | FG109: =AA34 -> 0 | FH109: =AF34 -> 0 | FI109: =AM34 -> 0
...

Sheet CLC1.5KW
M2: CODE | AA2: 御 見 積 書
E3: 〒063-0849 | AL3: No. | AN3: FL2504035
D4: 札幌市西区八軒9条西11丁目2-22
AG6: 令和 | AI6: 7 | AL6: 年 | AM6: 4 | AO6: 月 | AP6: 3 | AR6: 日
D7: サンワ機器販売株式会社 | T7: 様
D11: 受渡期日 | H11: 相談
D13: 受渡場所 | H13: 貴社住所車上渡し | AB13: 振込先： | AE13: 十六銀行 柳ヶ瀬支店 普通：0777577
D15: 取引方法 | I15: 末締め末払い | AB15: 名義： | AE15: ｶ)ﾘﾝｼｭﾝﾄﾞｳ
E17: 送 料 | G17: 別 | J17: 車上 | N17: 渡し | AB17: 担当者 | AF17: 田中 健吾
J19: =H39 -> 5830000
D20: 税込合計 | J20: =H39 -> 5830000
B22: 見積書有効期限発効後９０日
B24: 品 名 | T24: 数 量 | AA24: 税別単価 | AF24: 金 額 | AM24: 備 考
B26: 1台購入時 | AF26: =IF(T26="",1*AA26,T26*AA26) -> 0
B27: RSD-SUNMAX-FL-CLC 洗浄機（サビ取り・焼け取り） 1500w 剥離専用 | X27: 一式 | AA27: 1400000 | AF27: =IF(T27="",1*AA27,T27*AA27) -> 1400000 | AM27: 定価180万円
B28: 3台購入時 | AF28: =IF(T28="",1*AA28,T28*AA28) -> 0
B29: RSD-SUNMAX-FL-CLC 洗浄機（サビ取り・焼け取り） 1500w 剥離専用 | X29: 一式 | AA29: 1350000 | AF29: =IF(T29="",1*AA29,T29*AA29) -> 1350000 | AM29: 定価180万円
B30: 5台購入時 | AF30: =IF(T30="",1*AA30,T30*AA30) -> 0
B31: RSD-SUNMAX-FL-CLC 洗浄機（サビ取り・焼け取り） 1500w 剥離専用 | X31: 一式 | AA31: 1300000 | AF31: =IF(T31="",1*AA31,T31*AA31) -> 1300000 | AM31: 定価180万円
B32: 10台購入時 | AF32: =IF(T32="",1*AA32,T32*AA32) -> 0
B33: RSD-SUNMAX-FL-CLC 洗浄機（サビ取り・焼け取り） 1500w 剥離専用 | X33: 一式 | AA33: 1250000 | AF33: =IF(T33="",1*AA33,T33*AA33) -> 1250000 | AM33: 定価180万円
AF34: =IF(T34="",1*AA34,T34*AA34) -> 0
AF35: =IF(T35="",1*AA35,T35*AA35) -> 0
B36: 出張セットアップ 操作講習 | T36: 1 | X36: 一式 | AF36: =IF(T36="",1*AA36,T36*AA36) -> 0
B37: 送料 地域別 車上渡し | T37: 1 | X37: 一式 | AF37: =IF(T37="",1*AA37,T37*AA37) -> 0
B38: 消費税10% | H38: =AA38*0.1 -> 530000 | T38: 小 計 | AA38: =SUM(AF26:AL37) -> 5300000
B39: 合計金額 | H39: =CK115+H38 -> 5830000
B40: 摘要：
B41: 最初の納品から1ヵ月以内に全量納品
B42: 新品1年保証
P56: =SUM(CK115:CQ115) -> 5300000
FB100: NO | FC100: 明細NO | FD100: 品名 | FE100: 数量 | FF100: 単位 | FG100: 単位 | FH100: 金額 | FI100: 備考
FB101: 0 | FC101: 1 | FD101: =B26 -> 1台購入時 | FE101: =T26 -> 0 | FF101: =X26 -> 0 | FG101: =AA26 -> 0 | FH101: =AF26 -> 0 | FI101: =AM26 -> 0
EM102: ON | FB102: 0 | FC102: 2 | FD102: =B27 -> RSD-SUNMAX-FL-CLC 洗浄機（サビ取り・焼け取り） 1500w 剥離専用 | FE102: =T27 -> 0 | FF102: =X27 -> 一式 | FG102: =AA27 -> 1400000 | FH102: =AF27 -> 1400000 | FI102: =AM27 -> 定価180万円
CE103: 制御 | CI103: 総計 | CS103: 単位 | CW103: 消費税 | DD103: タイトル | DM103: ﾏｽﾀﾊﾞｯｸｱｯﾌﾟ | EM103: OFF | FB103: 0 | FC103: 3 | FD103: =B28 -> 3台購入時 | FE103: =T28 -> 0 | FF103: =X28 -> 0 | FG103: =AA28 -> 0 | FH103: =AF28 -> 0 | FI103: =AM28 -> 0
CE104: 3 | CI104: 0 | CK104: =AA38 -> 5300000 | CS104: 台 | CW104: 5 | CY104: ％ | DD104: 御 見 積 書 | DM104: ON | FB104: 0 | FC104: 4 | FD104: =B29 -> RSD-SUNMAX-FL-CLC 洗浄機（サビ取り・焼け取り） 1500w 剥離専用 | FE104: =T29 -> 0 | FF104: =X29 -> 一式 | FG104: =AA29 -> 1350000 | FH104: =AF29 -> 1350000 | FI104: =AM29 -> 定価180万円
CE105: =MAX(FB401:FB642) -> 0 | CI105: 1 | CK105: =IF(ISERROR(購入おすすめ品!AB30),0,購入おすすめ品!AB30) -> 0 | CS105: 個 | DD105: 納 品 書 | FB105: 0 | FC105: 5 | FD105: =#REF! -> #REF! | FE105: =T30 -> 0 | FF105: =X30 -> 0 | FG105: =AA30 -> 0 | FH105: =AF30 -> 0 | FI105: =AM30 -> 0
CE106: 1 | CI106: 2 | CK106: =IF(ISERROR(#REF!),0,#REF!) -> 0 | CS106: 一式 | CV106: 画面表示 | DD106: 納 品 書 （控） | DM106: ﾃﾞｰﾀ保存ｼｰﾄ | FB106: 0 | FC106: 6 | FD106: =#REF! -> #REF! | FE106: =T31 -> 0 | FF106: =X31 -> 一式 | FG106: =AA31 -> 1300000 | FH106: =AF31 -> 1300000 | FI106: =AM31 -> 定価180万円
CE107: 0 | CI107: 3 | CK107: =IF(ISERROR(#REF!),0,#REF!) -> 0 | CS107: 冊 | CV107: ① | CW107: 100 | CZ107: ％ | DD107: 請 求 書 | DM107: データ保存 1.xls | FB107: 0 | FC107: 7 | FD107: =#REF! -> #REF! | FE107: =T32 -> 0 | FF107: =X32 -> 0 | FG107: =AA32 -> 0 | FH107: =AF32 -> 0 | FI107: =AM32 -> 0
CE108: 敬称 | CI108: 4 | CS108: 箱 | CV108: ② | CW108: 80 | CZ108: ％ | DD108: 請 求 書 （控） | DM108: 鑑 | FB108: 0 | FC108: 8 | FD108: =B31 -> RSD-SUNMAX-FL-CLC 洗浄機（サビ取り・焼け取り） 1500w 剥離専用 | FE108: =T33 -> 0 | FF108: =X33 -> 一式 | FG108: =AA33 -> 1250000 | FH108: =AF33 -> 1250000 | FI108: =AM33 -> 定価180万円
...

Sheet CLC2kw_3kw
M2: CODE | AA2: 御 見 積 書
E3: 〒063-0849 | AL3: No. | AN3: FL2509045
D4: 札幌市西区八軒9条西11丁目2-22
AG6: 令和 | AI6: 7 | AL6: 年 | AM6: 9 | AO6: 月 | AP6: 4 | AR6: 日
D7: サンワ機器販売株式会社 | T7: 様
D11: 受渡期日 | H11: 2～3か月 （2kw 3kw）
D13: 受渡場所 | H13: 貴社住所車上渡し | AB13: 振込先： | AE13: 十六銀行 柳ヶ瀬支店 普通：0777577
D15: 取引方法 | I15: 納品末締め末払い | AB15: 名義： | AE15: ｶ)ﾘﾝｼｭﾝﾄﾞｳ
E17: 送 料 | G17: 別 | J17: 車上 | N17: 渡し | AB17: 担当者 | AF17: 田中 健吾
J19: =H39 -> 13607000
D20: 税込合計 | J20: =H39 -> 13607000
B22: 見積書有効期限発効後９０日
B24: 品 名 | T24: 数 量 | AA24: 税別単価 | AF24: 金 額 | AM24: 備 考
B26: 1台購入時 | AF26: =IF(T26="",1*AA26,T26*AA26) -> 0
B27: RSD-SUNMAX-FL-CLC 洗浄機（サビ取り・焼け取り） 1500w 剥離専用 | X27: 一式 | AA27: 1400000 | AF27: =IF(T27="",1*AA27,T27*AA27) -> 1400000 | AM27: 定価180万円
B28: 3台購入時 | AF28: =IF(T28="",1*AA28,T28*AA28) -> 0
B29: RSD-SUNMAX-FL-CLC 洗浄機（サビ取り・焼け取り） 1500w 剥離専用 | X29: 一式 | AA29: 1350000 | AF29: =IF(T29="",1*AA29,T29*AA29) -> 1350000 | AM29: 定価180万円
B30: 1台購入時 | AF30: =IF(T30="",1*AA30,T30*AA30) -> 0
B31: RSD-SUNMAX-FL-CLC 洗浄機（サビ取り・焼け取り）2000w 剥離専用 | X31: 一式 | AA31: 1980000 | AF31: =IF(T31="",1*AA31,T31*AA31) -> 1980000 | AM31: 定価248万円
B32: 3台購入時 | AF32: =IF(T32="",1*AA32,T32*AA32) -> 0
B33: RSD-SUNMAX-FL-CLC 洗浄機（サビ取り・焼け取り） 2000w 剥離専用 | X33: 一式 | AA33: 1930000 | AF33: =IF(T33="",1*AA33,T33*AA33) -> 1930000 | AM33: 定価248万円
B34: 1台購入時 | AF34: =IF(T34="",1*AA34,T34*AA34) -> 0
B35: RSD-SUNMAX-FL-CLC 洗浄機（サビ取り・焼け取り） 3000w 剥離専用 | X35: 一式 | AA35: 2880000 | AF35: =IF(T35="",1*AA35,T35*AA35) -> 2880000 | AM35: 定価348万円
B36: 3台購入時 | AF36: =IF(T36="",1*AA36,T36*AA36) -> 0
B37: RSD-SUNMAX-FL-CLC 洗浄機（サビ取り・焼け取り） 3000w 剥離専用 変圧器付属 | X37: 一式 | AA37: 2830000 | AF37: =IF(T37="",1*AA37,T37*AA37) -> 2830000 | AM37: 定価348万円
B38: 消費税10% | H38: =AA38*0.1 -> 1237000 | T38: 小 計 | AA38: =SUM(AF26:AL37) -> 12370000
B39: 合計金額 | H39: =CK115+H38 -> 13607000
B40: 摘要： | E40: 別途 運賃 セットアップ 操作講習費別
B41: 最初の納品から1ヵ月以内に全量納品
B42: 新品1年保証
P56: =SUM(CK115:CQ115) -> 12370000
FB100: NO | FC100: 明細NO | FD100: 品名 | FE100: 数量 | FF100: 単位 | FG100: 単位 | FH100: 金額 | FI100: 備考
FB101: 0 | FC101: 1 | FD101: =B26 -> 1台購入時 | FE101: =T26 -> 0 | FF101: =X26 -> 0 | FG101: =AA26 -> 0 | FH101: =AF26 -> 0 | FI101: =AM26 -> 0
EM102: ON | FB102: 0 | FC102: 2 | FD102: =B27 -> RSD-SUNMAX-FL-CLC 洗浄機（サビ取り・焼け取り） 1500w 剥離専用 | FE102: =T27 -> 0 | FF102: =X27 -> 一式 | FG102: =AA27 -> 1400000 | FH102: =AF27 -> 1400000 | FI102: =AM27 -> 定価180万円
CE103: 制御 | CI103: 総計 | CS103: 単位 | CW103: 消費税 | DD103: タイトル | DM103: ﾏｽﾀﾊﾞｯｸｱｯﾌﾟ | EM103: OFF | FB103: 0 | FC103: 3 | FD103: =B28 -> 3台購入時 | FE103: =T28 -> 0 | FF103: =X28 -> 0 | FG103: =AA28 -> 0 | FH103: =AF28 -> 0 | FI103: =AM28 -> 0
CE104: 3 | CI104: 0 | CK104: =AA38 -> 12370000 | CS104: 台 | CW104: 5 | CY104: ％ | DD104: 御 見 積 書 | DM104: ON | FB104: 0 | FC104: 4 | FD104: =B29 -> RSD-SUNMAX-FL-CLC 洗浄機（サビ取り・焼け取り） 1500w 剥離専用 | FE104: =T29 -> 0 | FF104: =X29 -> 一式 | FG104: =AA29 -> 1350000 | FH104: =AF29 -> 1350000 | FI104: =AM29 -> 定価180万円
CE105: =MAX(FB401:FB642) -> 0 | CI105: 1 | CK105: =IF(ISERROR(購入おすすめ品!AB30),0,購入おすすめ品!AB30) -> 0 | CS105: 個 | DD105: 納 品 書 | FB105: 0 | FC105: 5 | FD105: =#REF! -> #REF! | FE105: =T30 -> 0 | FF105: =X30 -> 0 | FG105: =AA30 -> 0 | FH105: =AF30 -> 0 | FI105: =AM30 -> 0
CE106: 1 | CI106: 2 | CK106: =IF(ISERROR(#REF!),0,#REF!) -> 0 | CS106: 一式 | CV106: 画面表示 | DD106: 納 品 書 （控） | DM106: ﾃﾞｰﾀ保存ｼｰﾄ | FB106: 0 | FC106: 6 | FD106: =#REF! -> #REF! | FE106: =T31 -> 0 | FF106: =X31 -> 一式 | FG106: =AA31 -> 1980000 | FH106: =AF31 -> 1980000 | FI106: =AM31 -> 定価248万円
CE107: 0 | CI107: 3 | CK107: =IF(ISERROR(#REF!),0,#REF!) -> 0 | CS107: 冊 | CV107: ① | CW107: 100 | CZ107: ％ | DD107: 請 求 書 | DM107: データ保存 1.xls | FB107: 0 | FC107: 7 | FD107: =#REF! -> #REF! | FE107: =T32 -> 0 | FF107: =X32 -> 0 | FG107: =AA32 -> 0 | FH107: =AF32 -> 0 | FI107: =AM32 -> 0
CE108: 敬称 | CI108: 4 | CS108: 箱 | CV108: ② | CW108: 80 | CZ108: ％ | DD108: 請 求 書 （控） | DM108: 鑑 | FB108: 0 | FC108: 8 | FD108: =B31 -> RSD-SUNMAX-FL-CLC 洗浄機（サビ取り・焼け取り）2000w 剥離専用 | FE108: =T33 -> 0 | FF108: =X33 -> 一式 | FG108: =AA33 -> 1930000 | FH108: =AF33 -> 1930000 | FI108: =AM33 -> 定価248万円
...

Sheet 工具箱内一覧
D3: 工具箱内付属一覧 | AL3: No.
C5: 付 属 品 名 | U5: 数 量 | AB5: 単 価 | AG5: 金 額 | AN5: 備 考
C7: USBメモリー(取説・設定表・レンズ清掃方法 など) | U7: 1 | Y7: 一式 | AG7: =IF(U7="",1*AB7,U7*AB7) -> 0
C8: 保護メガネ | U8: 2 | Y8: 個 | AG8: =IF(U8="",1*AB8,U8*AB8) -> 0
C9: 六角レンチ | U9: 1 | Y9: 個 | AG9: =IF(U9="",1*AB9,U9*AB9) -> 0
C10: 保護レンズ | U10: 3 | Y10: 個 | AG10: =IF(U10="",1*AB10,U10*AB10) -> 0
C11: エアホース | U11: 1 | Y11: 個 | AG11: =IF(U11="",1*AB11,U11*AB11) -> 0
C12: レンズ清掃用綿棒 | U12: 20 | Y12: 本 | AG12: =IF(U12="",1*AB12,U12*AB12) -> 0
C13: レンズ清掃用クリーナー | U13: 1 | Y13: 個 | AG13: =IF(U13="",1*AB13,U13*AB13) -> 0
C14: 発振器接続用ケーブル | U14: 1 | Y14: 個 | AG14: =IF(U14="",1*AB14,U14*AB14) -> 0
AG15: =IF(U15="",1*AB15,U15*AB15) -> 0
AG16: =IF(U16="",1*AB16,U16*AB16) -> 0
AG17: =IF(U17="",1*AB17,U17*AB17) -> 0
AG18: =IF(U18="",1*AB18,U18*AB18) -> 0
AG19: =IF(U19="",1*AB19,U19*AB19) -> 0
AG20: =IF(U20="",1*AB20,U20*AB20) -> 0
AG21: =IF(U21="",1*AB21,U21*AB21) -> 0
AG22: =IF(U22="",1*AB22,U22*AB22) -> 0
AG23: =IF(U23="",1*AB23,U23*AB23) -> 0
AG24: =IF(U24="",1*AB24,U24*AB24) -> 0
AG25: =IF(U25="",1*AB25,U25*AB25) -> 0
AG26: =IF(U26="",1*AB26,U26*AB26) -> 0
... AG28: =IF(U28="",1*AB28,U28*AB28) -> 0
B29: FAX感熱紙(A4) | AG29: =IF(U29="",1*AB29,U29*AB29) -> 0
U30: 小 計
CS103: 単位
CS104: ='CLC1.5KW'!CS104 -> 台
CS105: ='CLC1.5KW'!CS105 -> 個
CS106: ='CLC1.5KW'!CS106 -> 一式
CS107: ='CLC1.5KW'!CS107 -> 冊
CS108: ='CLC1.5KW'!CS108 -> 箱
CS109: ='CLC1.5KW'!CS109 -> C/S
CS110: ='CLC1.5KW'!CS110 -> SET
CS111: ='CLC1.5KW'!CS111 -> 本
CS112: ='CLC1.5KW'!CS112 -> 束
CS113: ='CLC1.5KW'!CS113 -> 枚
CS114: ='CLC1.5KW'!CS114 -> ﾊﾟｯｸ
CS115: ='CLC1.5KW'!CS115 -> ｷｯﾄ
CS116: ='CLC1.5KW'!CS116 -> 0
CI119: マスタパス | CM119: ='CLC1.5KW'!CM119 -> C:\Documents and Settings\sato\My Documents\シンプル見積書\ | DO119: ='CLC1.5KW'!$DO$119 -> マスタ 1.xls
...

Sheet CLC付属品

Sheet 購入おすすめ品
D3: 本体装備品一覧 | AL3: No.
C5: 付 属 品 名 | U5: 数 量 | AB5: 単 価 | AG5: 金 額 | AN5: 備 考
AB7: =SUM(Y19) -> 0 | AG7: =IF(U7="",1*AB7,U7*AB7) -> 0
AG8: =IF(U8="",1*AB8,U8*AB8) -> 0
AG9: =IF(U9="",1*AB9,U9*AB9) -> 0
AG10: =IF(U10="",1*AB10,U10*AB10) -> 0
AG11: =IF(U11="",1*AB11,U11*AB11) -> 0
AG12: =IF(U12="",1*AB12,U12*AB12) -> 0
AG13: =IF(U13="",1*AB13,U13*AB13) -> 0
AG14: =IF(U14="",1*AB14,U14*AB14) -> 0
AG15: =IF(U15="",1*AB15,U15*AB15) -> 0
AG16: =IF(U16="",1*AB16,U16*AB16) -> 0
AG17: =IF(U17="",1*AB17,U17*AB17) -> 0
AG18: =IF(U18="",1*AB18,U18*AB18) -> 0
AG19: =IF(U19="",1*AB19,U19*AB19) -> 0
... AG28: =IF(U28="",1*AB28,U28*AB28) -> 0
B29: FAX感熱紙(A4) | AG29: =IF(U29="",1*AB29,U29*AB29) -> 0
U30: 小 計
CS103: 単位
CS104: ='CLC1.5KW'!CS104 -> 台
CS105: ='CLC1.5KW'!CS105 -> 個
CS106: ='CLC1.5KW'!CS106 -> 一式
CS107: ='CLC1.5KW'!CS107 -> 冊
CS108: ='CLC1.5KW'!CS108 -> 箱
CS109: ='CLC1.5KW'!CS109 -> C/S
CS110: ='CLC1.5KW'!CS110 -> SET
CS111: ='CLC1.5KW'!CS111 -> 本
CS112: ='CLC1.5KW'!CS112 -> 束
CS113: ='CLC1.5KW'!CS113 -> 枚
CS114: ='CLC1.5KW'!CS114 -> ﾊﾟｯｸ
CS115: ='CLC1.5KW'!CS115 -> ｷｯﾄ
CS116: ='CLC1.5KW'!CS116 -> 0
CI119: マスタパス | CM119: ='CLC1.5KW'!CM119 -> C:\Documents and Settings\sato\My Documents\シンプル見積書\ | DO119: ='CLC1.5KW'!$DO$119 -> マスタ 1.xls
CI120: データパス | CM120: ='CLC1.5KW'!CM120 -> 0
P178: ='CLC1.5KW'!P177 -> 0

Sheet USBフラッシュメモリ内一覧
