Workbook

Sheet 新潟マルテーフェア
M2: CODE | AA2: 御 見 積 書
E3: 〒160-8511 | AL3: No. | AN3: FL2503195
D4: 東京都新宿区四谷4-1
AG6: 令和 | AI6: 7 | AL6: 年 | AM6: 3 | AO6: 月 | AP6: 19 | AR6: 日
D7: 大塚刷毛製造株式会社 | T7: 様
D11: 期日 | H11: 2025/4/5-6
D13: 場所 | H13: 新潟マルテーフェア | AB13: 振込先： | AE13: 十六銀行 柳ヶ瀬支店 普通：0777577
D15: 現金支払 | I15: 末締め末現金払い | AB15: 名義： | AE15: ｶ)ﾘﾝｼｭﾝﾄﾞｳ
AB17: 担当者 | AF17: 田中 健吾
J19: =H39 -> 237754
D20: 税込合計 | J20: =H39 -> 237754
B22: 見積書有効期限発効後60日
B24: 品 名 | T24: 数 量 | AA24: 税別単価 | AF24: 金 額 | AM24: 備 考
B26: 展示会 R7/4/5-6 | AF26: =IF(T26="",1*AA26,T26*AA26) -> 0
B27: 交通費 岐阜-新潟 片道 5 時間 41 分（448 km） | X27: 一式 | AA27: 72280 | AF27: =IF(T27="",1*AA27,T27*AA27) -> 72280 | AM27: ETC18,520円
AF28: =IF(T28="",1*AA28,T28*AA28) -> 0
B29: 宿泊費 3泊4日 | X29: 一式 | AA29: 45000 | AF29: =IF(T29="",1*AA29,T29*AA29) -> 45000
B30: 日当 2日分 平日 | X30: 一式 | AA30: 100000 | AF30: =IF(T30="",1*AA30,T30*AA30) -> 100000
B31: 日当 2日分 土日 | X31: 一式 | AA31: 150000 | AF31: =IF(T31="",1*AA31,T31*AA31) -> 150000
B32: 展示会参加デモ用消耗品費 | X32: 一式 | AA32: 15000 | AF32: =IF(T32="",1*AA32,T32*AA32) -> 15000
B33: FL-LCW デモ機追加設置費用 錆び取り専用として | X33: 一式 | AA33: 50000 | AF33: =IF(T33="",1*AA33,T33*AA33) -> 50000
AF34: =IF(T34="",1*AA34,T34*AA34) -> 0
B35: 代理店協力50％値引き | X35: 一式 | AA35: -216140 | AF35: =IF(T35="",1*AA35,T35*AA35) -> -216140
B36: 遮光パネル 溶接用机 ご用意ください。 | AF36: =IF(T36="",1*AA36,T36*AA36) -> 0
B37: デモ機の搬入撤収時男性3名手伝い要します。 | AF37: =IF(T37="",1*AA37,T37*AA37) -> 0
B38: 消費税10% | H38: =AA38*0.1 -> 21614 | T38: 小 計 | AA38: =SUM(AF26:AL37) -> 216140
B39: 合計金額 | H39: =CK115+H38 -> 237754
B40: 摘要：
P56: =SUM(CK115:CQ115) -> 216140
FB100: NO | FC100: 明細NO | FD100: 品名 | FE100: 数量 | FF100: 単位 | FG100: 単位 | FH100: 金額 | FI100: 備考
FB101: 0 | FC101: 1 | FD101: =B26 -> 展示会 R7/4/5-6 | FE101: =T26 -> 0 | FF101: =X26 -> 0 | FG101: =AA26 -> 0 | FH101: =AF26 -> 0 | FI101: =AM26 -> 0
EM102: ON | FB102: 0 | FC102: 2 | FD102: =B27 -> 交通費 岐阜-新潟 片道 5 時間 41 分（448 km） | FE102: =T27 -> 0 | FF102: =X27 -> 一式 | FG102: =AA27 -> 72280 | FH102: =AF27 -> 72280 | FI102: =AM27 -> ETC18,520円
CE103: 制御 | CI103: 総計 | CS103: 単位 | CW103: 消費税 | DD103: タイトル | DM103: ﾏｽﾀﾊﾞｯｸｱｯﾌﾟ | EM103: OFF | FB103: 0 | FC103: 3 | FD103: =B28 -> 0 | FE103: =T28 -> 0 | FF103: =X28 -> 0 | FG103: =AA28 -> 0 | FH103: =AF28 -> 0 | FI103: =AM28 -> 0
CE104: 3 | CI104: 0 | CK104: =AA38 -> 216140 | CS104: 台 | CW104: 5 | CY104: ％ | DD104: 御 見 積 書 | DM104: ON | FB104: 0 | FC104: 4 | FD104: =B29 -> 宿泊費 3泊4日 | FE104: =T29 -> 0 | FF104: =X29 -> 一式 | FG104: =AA29 -> 45000 | FH104: =AF29 -> 45000 | FI104: =AM29 -> 0
CE105: =MAX(FB401:FB642) -> 0 | CI105: 1 | CK105: =IF(ISERROR(#REF!),0,#REF!) -> 0 | CS105: 個 | DD105: 納 品 書 | FB105: 0 | FC105: 5 | FD105: =#REF! -> #REF! | FE105: =T30 -> 0 | FF105: =X30 -> 一式 | FG105: =AA30 -> 100000 | FH105: =AF30 -> 100000 | FI105: =AM30 -> 0
CE106: 1 | CI106: 2 | CK106: =IF(ISERROR(#REF!),0,#REF!) -> 0 | CS106: 一式 | CV106: 画面表示 | DD106: 納 品 書 （控） | DM106: ﾃﾞｰﾀ保存ｼｰﾄ | FB106: 0 | FC106: 6 | FD106: =#REF! -> #REF! | FE106: =T31 -> 0 | FF106: =X31 -> 一式 | FG106: =AA31 -> 150000 | FH106: =AF31 -> 150000 | FI106: =AM31 -> 0
CE107: 0 | CI107: 3 | CK107: =IF(ISERROR(#REF!),0,#REF!) -> 0 | CS107: 冊 | CV107: ① | CW107: 100 | CZ107: ％ | DD107: 請 求 書 | DM107: データ保存 1.xls | FB107: 0 | FC107: 7 | FD107: =#REF! -> #REF! | FE107: =T32 -> 0 | FF107: =X32 -> 一式 | FG107: =AA32 -> 15000 | FH107: =AF32 -> 15000 | FI107: =AM32 -> 0
CE108: 敬称 | CI108: 4 | CS108: 箱 | CV108: ② | CW108: 80 | CZ108: ％ | DD108: 請 求 書 （控） | DM108: 鑑 | FB108: 0 | FC108: 8 | FD108: =B31 -> 日当 2日分 土日 | FE108: =T33 -> 0 | FF108: =X33 -> 一式 | FG108: =AA33 -> 50000 | FH108: =AF33 -> 50000 | FI108: =AM33 -> 0
CE109: 御中 | CI109: 5 | CS109: C/S | DM109: 明細 | FB109: 0 | FC109: 9 | FD109: =B34 -> 0 | FE109: =T34 -> 0 | FF109: =X34 -> 0 | FG109: =AA34 -> 0 | FH109: =AF34 -> 0 | FI109: =AM34 -> 0
CE110: 様 | CI110: 6 | CS110: SET | CV110: 画像ファイル名 | DE110: 画像名 | FB110: 0 | FC110: 10 | FD110: =B35 -> 代理店協力50％値引き | FE110: =T35 -> 0 | FF110: =X35 -> 一式 | FG110: =AA35 -> -216140 | FH110: =AF35 -> -216140 | FI110: =AM35 -> 0
...

Sheet オートビジネス2025
M2: CODE | AA2: 御 見 積 書
E3: 〒922-0857 | AL3: No. | AN3: FL2505085
D4: 石川県加賀市永井町89
F6: 北陸営業所 | AG6: 令和 | AI6: 7 | AL6: 年 | AM6: 5 | AO6: 月 | AP6: 8 | AR6: 日
D7: 大塚刷毛製造株式会社 | T7: 様
D11: 期日 | H11: 2025/9/5-6
D13: 場所 | H13: オートビジネスフェアKYOTO2025 | AB13: 振込先： | AE13: 十六銀行 柳ヶ瀬支店 普通：0777577
D15: 現金支払 | I15: 末締め末現金払い | AB15: 名義： | AE15: ｶ)ﾘﾝｼｭﾝﾄﾞｳ
AB17: 担当者 | AF17: 田中 健吾
J19: =H39 -> 129668
D20: 税込合計 | J20: =H39 -> 129668
B22: 見積書有効期限発効後60日
B24: 品 名 | T24: 数 量 | AA24: 税別単価 | AF24: 金 額 | AM24: 備 考
B26: 展示会参加諸経費 | AF26: =IF(T26="",1*AA26,T26*AA26) -> 0
B27: 交通費 岐阜-新潟 片道 2 時間 12 分（154 km） | T27: 1 | X27: 台 | AA27: 18480 | AF27: =IF(T27="",1*AA27,T27*AA27) -> 18480 | AM27: 10k＝600円
B28: ETC利用料金 | T28: 1 | X28: 台 | AA28: 7280 | AF28: =IF(T28="",1*AA28,T28*AA28) -> 7280
B29: 宿泊費 1泊2日 1名分 | X29: 一式 | AA29: 15000 | AF29: =IF(T29="",1*AA29,T29*AA29) -> 15000
B30: 日当１日分 平日 | X30: 一式 | AA30: 50000 | AF30: =IF(T30="",1*AA30,T30*AA30) -> 50000
B31: 日当１日分 土日 | X31: 一式 | AA31: 75000 | AF31: =IF(T31="",1*AA31,T31*AA31) -> 75000
B32: 展示会参加デモ用消耗品費 | X32: 一式 | AA32: 17500 | AF32: =IF(T32="",1*AA32,T32*AA32) -> 17500
B33: FL-LCW デモ機追加設置費用LCW1.5kw錆び取り | X33: 一式 | AA33: 50000 | AF33: =IF(T33="",1*AA33,T33*AA33) -> 50000
AF34: =IF(T34="",1*AA34,T34*AA34) -> 0
B35: 代理店協力50％値引き | X35: 一式 | AA35: -115380 | AF35: =IF(T35="",1*AA35,T35*AA35) -> -115380
B36: 遮光パネル付き溶接台準備します。 | AF36: =IF(T36="",1*AA36,T36*AA36) -> 0
B37: デモ機の搬入撤収時男性3名手伝い要します。 | AF37: =IF(T37="",1*AA37,T37*AA37) -> 0
B38: 消費税10% | H38: =AA38*0.1 -> 11788 | T38: 小 計 | AA38: =SUM(AF26:AL37) -> 117880
B39: 合計金額 | H39: =CK115+H38 -> 129668
B40: 摘要：
P56: =SUM(CK115:CQ115) -> 117880
FB100: NO | FC100: 明細NO | FD100: 品名 | FE100: 数量 | FF100: 単位 | FG100: 単位 | FH100: 金額 | FI100: 備考
FB101: 0 | FC101: 1 | FD101: =B26 -> 展示会参加諸経費 | FE101: =T26 -> 0 | FF101: =X26 -> 0 | FG101: =AA26 -> 0 | FH101: =AF26 -> 0 | FI101: =AM26 -> 0
EM102: ON | FB102: 0 | FC102: 2 | FD102: =B27 -> 交通費 岐阜-新潟 片道 2 時間 12 分（154 km） | FE102: =T27 -> 1 | FF102: =X27 -> 台 | FG102: =AA27 -> 18480 | FH102: =AF27 -> 18480 | FI102: =AM27 -> 10k＝600円
CE103: 制御 | CI103: 総計 | CS103: 単位 | CW103: 消費税 | DD103: タイトル | DM103: ﾏｽﾀﾊﾞｯｸｱｯﾌﾟ | EM103: OFF | FB103: 0 | FC103: 3 | FD103: =B28 -> ETC利用料金 | FE103: =T28 -> 1 | FF103: =X28 -> 台 | FG103: =AA28 -> 7280 | FH103: =AF28 -> 7280 | FI103: =AM28 -> 0
CE104: 3 | CI104: 0 | CK104: =AA38 -> 117880 | CS104: 台 | CW104: 5 | CY104: ％ | DD104: 御 見 積 書 | DM104: ON | FB104: 0 | FC104: 4 | FD104: =B29 -> 宿泊費 1泊2日 1名分 | FE104: =T29 -> 0 | FF104: =X29 -> 一式 | FG104: =AA29 -> 15000 | FH104: =AF29 -> 15000 | FI104: =AM29 -> 0
CE105: =MAX(FB401:FB642) -> 0 | CI105: 1 | CK105: =IF(ISERROR(#REF!),0,#REF!) -> 0 | CS105: 個 | DD105: 納 品 書 | FB105: 0 | FC105: 5 | FD105: =#REF! -> #REF! | FE105: =T30 -> 0 | FF105: =X30 -> 一式 | FG105: =AA30 -> 50000 | FH105: =AF30 -> 50000 | FI105: =AM30 -> 0
CE106: 1 | CI106: 2 | CK106: =IF(ISERROR(#REF!),0,#REF!) -> 0 | CS106: 一式 | CV106: 画面表示 | DD106: 納 品 書 （控） | DM106: ﾃﾞｰﾀ保存ｼｰﾄ | FB106: 0 | FC106: 6 | FD106: =#REF! -> #REF! | FE106: =T31 -> 0 | FF106: =X31 -> 一式 | FG106: =AA31 -> 75000 | FH106: =AF31 -> 75000 | FI106: =AM31 -> 0
CE107: 0 | CI107: 3 | CK107: =IF(ISERROR(#REF!),0,#REF!) -> 0 | CS107: 冊 | CV107: ① | CW107: 100 | CZ107: ％ | DD107: 請 求 書 | DM107: データ保存 1.xls | FB107: 0 | FC107: 7 | FD107: =#REF! -> #REF! | FE107: =T32 -> 0 | FF107: =X32 -> 一式 | FG107: =AA32 -> 17500 | FH107: =AF32 -> 17500 | FI107: =AM32 -> 0
CE108: 敬称 | CI108: 4 | CS108: 箱 | CV108: ② | CW108: 80 | CZ108: ％ | DD108: 請 求 書 （控） | DM108: 鑑 | FB108: 0 | FC108: 8 | FD108: =B31 -> 日当１日分 土日 | FE108: =T33 -> 0 | FF108: =X33 -> 一式 | FG108: =AA33 -> 50000 | FH108: =AF33 -> 50000 | FI108: =AM33 -> 0
CE109: 御中 | CI109: 5 | CS109: C/S | DM109: 明細 | FB109: 0 | FC109: 9 | FD109: =B34 -> 0 | FE109: =T34 -> 0 | FF109: =X34 -> 0 | FG109: =AA34 -> 0 | FH109: =AF34 -> 0 | FI109: =AM34 -> 0
CE110: 様 | CI110: 6 | CS110: SET | CV110: 画像ファイル名 | DE110: 画像名 | FB110: 0 | FC110: 10 | FD110: =B35 -> 代理店協力50％値引き | FE110: =T35 -> 0 | FF110: =X35 -> 一式 | FG110: =AA35 -> -115380 | FH110: =AF35 -> -115380 | FI110: =AM35 -> 0
...

Sheet 群馬フジペックスフェア
M2: CODE | AA2: 御 見 積 書
E3: 〒160-8511 | AL3: No. | AN3: FL2507186
D4: 東京都新宿区四谷4-1
AG6: 令和 | AI6: 7 | AL6: 年 | AM6: 7 | AO6: 月 | AP6: 18 | AR6: 日
D7: 大塚刷毛製造株式会社 | T7: 様
D11: 期日 | H11: 2025/9/6-7
D13: 場所 | H13: 群馬県太田市吉沢町1058-5 | AB13: 振込先： | AE13: 十六銀行 柳ヶ瀬支店 普通：0777577
D15: 現金支払 | I15: 末締め末現金払い | AB15: 名義： | AE15: ｶ)ﾘﾝｼｭﾝﾄﾞｳ
AB17: 担当者 | AF17: 田中 健吾
J19: =H39 -> 220000
D20: 税込合計 | J20: =H39 -> 220000
B24: 品 名 | T24: 数 量 | AA24: 税別単価 | AF24: 金 額 | AM24: 備 考
B26: 展示会参加諸経費 9/6土曜 9/7日曜 | AF26: =IF(T26="",1*AA26,T26*AA26) -> 0
B27: 交通費 往復 岐阜-太田市 商用車使用 | X27: 一式 | AA27: 50000 | AF27: =IF(T27="",1*AA27,T27*AA27) -> 50000
B28: ETC利用料金 | X28: 一式 | AA28: 19400 | AF28: =IF(T28="",1*AA28,T28*AA28) -> 19400
B29: 宿泊費 1泊2日 2名分 | X29: 一式 | AA29: 30000 | AF29: =IF(T29="",1*AA29,T29*AA29) -> 30000
B30: 日当１日1名分 土日 | T30: 4 | X30: 一式 | AA30: 75000 | AF30: =IF(T30="",1*AA30,T30*AA30) -> 300000
B31: FL-LCW デモ機展示設置費用LCW1.5kw | X31: 一式 | AA31: 20000 | AF31: =IF(T31="",1*AA31,T31*AA31) -> 20000
B32: 展示会参加デモ用消耗品費 | X32: 一式 | AA32: 15000 | AF32: =IF(T32="",1*AA32,T32*AA32) -> 15000
B33: 保護メガネ５人分程度、手袋、溶接台 弊社手配 | X33: 一式 | AA33: 10000 | AF33: =IF(T33="",1*AA33,T33*AA33) -> 10000
B34: 追加値引き | X34: 一式 | AA34: -22200 | AF34: =IF(T34="",1*AA34,T34*AA34) -> -22200
B35: 出展協力50％値引き | X35: 一式 | AA35: -222200 | AF35: =IF(T35="",1*AA35,T35*AA35) -> -222200
B36: 電源 遮光パネル 窒素 御社手配 | AF36: =IF(T36="",1*AA36,T36*AA36) -> 0
B37: デモ機の搬入撤収時男性お手伝い要します。 | AF37: =IF(T37="",1*AA37,T37*AA37) -> 0
B38: 消費税10% | H38: =AA38*0.1 -> 20000 | T38: 小 計 | AA38: =SUM(AF26:AL37) -> 200000
B39: 合計金額 | H39: =CK115+H38 -> 220000
B40: 摘要： | E40: 発注書No2489059
B41: 太田市産業支援センター 〒373-0019群馬県太田市吉沢町1058-5
P56: =SUM(CK115:CQ115) -> 200000
FB100: NO | FC100: 明細NO | FD100: 品名 | FE100: 数量 | FF100: 単位 | FG100: 単位 | FH100: 金額 | FI100: 備考
FB101: 0 | FC101: 1 | FD101: =B26 -> 展示会参加諸経費 9/6土曜 9/7日曜 | FE101: =T26 -> 0 | FF101: =X26 -> 0 | FG101: =AA26 -> 0 | FH101: =AF26 -> 0 | FI101: =AM26 -> 0
EM102: ON | FB102: 0 | FC102: 2 | FD102: =B27 -> 交通費 往復 岐阜-太田市 商用車使用 | FE102: =T27 -> 0 | FF102: =X27 -> 一式 | FG102: =AA27 -> 50000 | FH102: =AF27 -> 50000 | FI102: =AM27 -> 0
CE103: 制御 | CI103: 総計 | CS103: 単位 | CW103: 消費税 | DD103: タイトル | DM103: ﾏｽﾀﾊﾞｯｸｱｯﾌﾟ | EM103: OFF | FB103: 0 | FC103: 3 | FD103: =B28 -> ETC利用料金 | FE103: =T28 -> 0 | FF103: =X28 -> 一式 | FG103: =AA28 -> 19400 | FH103: =AF28 -> 19400 | FI103: =AM28 -> 0
CE104: 3 | CI104: 0 | CK104: =AA38 -> 200000 | CS104: 台 | CW104: 5 | CY104: ％ | DD104: 御 見 積 書 | DM104: ON | FB104: 0 | FC104: 4 | FD104: =B29 -> 宿泊費 1泊2日 2名分 | FE104: =T29 -> 0 | FF104: =X29 -> 一式 | FG104: =AA29 -> 30000 | FH104: =AF29 -> 30000 | FI104: =AM29 -> 0
CE105: =MAX(FB401:FB642) -> 0 | CI105: 1 | CK105: =IF(ISERROR(#REF!),0,#REF!) -> 0 | CS105: 個 | DD105: 納 品 書 | FB105: 0 | FC105: 5 | FD105: =#REF! -> #REF! | FE105: =T30 -> 4 | FF105: =X30 -> 一式 | FG105: =AA30 -> 75000 | FH105: =AF30 -> 300000 | FI105: =AM30 -> 0
CE106: 1 | CI106: 2 | CK106: =IF(ISERROR(#REF!),0,#REF!) -> 0 | CS106: 一式 | CV106: 画面表示 | DD106: 納 品 書 （控） | DM106: ﾃﾞｰﾀ保存ｼｰﾄ | FB106: 0 | FC106: 6 | FD106: =#REF! -> #REF! | FE106: =T31 -> 0 | FF106: =X31 -> 一式 | FG106: =AA31 -> 20000 | FH106: =AF31 -> 20000 | FI106: =AM31 -> 0
CE107: 0 | CI107: 3 | CK107: =IF(ISERROR(#REF!),0,#REF!) -> 0 | CS107: 冊 | CV107: ① | CW107: 100 | CZ107: ％ | DD107: 請 求 書 | DM107: データ保存 1.xls | FB107: 0 | FC107: 7 | FD107: =#REF! -> #REF! | FE107: =T32 -> 0 | FF107: =X32 -> 一式 | FG107: =AA32 -> 15000 | FH107: =AF32 -> 15000 | FI107: =AM32 -> 0
CE108: 敬称 | CI108: 4 | CS108: 箱 | CV108: ② | CW108: 80 | CZ108: ％ | DD108: 請 求 書 （控） | DM108: 鑑 | FB108: 0 | FC108: 8 | FD108: =B31 -> FL-LCW デモ機展示設置費用LCW1.5kw | FE108: =T33 -> 0 | FF108: =X33 -> 一式 | FG108: =AA33 -> 10000 | FH108: =AF33 -> 10000 | FI108: =AM33 -> 0
CE109: 御中 | CI109: 5 | CS109: C/S | DM109: 明細 | FB109: 0 | FC109: 9 | FD109: =B34 -> 追加値引き | FE109: =T34 -> 0 | FF109: =X34 -> 一式 | FG109: =AA34 -> -22200 | FH109: =AF34 -> -22200 | FI109: =AM34 -> 0
CE110: 様 | CI110: 6 | CS110: SET | CV110: 画像ファイル名 | DE110: 画像名 | FB110: 0 | FC110: 10 | FD110: =B35 -> 出展協力50％値引き | FE110: =T35 -> 0 | FF110: =X35 -> 一式 | FG110: =AA35 -> -222200 | FH110: =AF35 -> -222200 | FI110: =AM35 -> 0
...

Sheet 城東営業所展示会
M2: CODE | AA2: 請 求 書
E3: 〒160-8511 | AL3: No. | AN3: FL2507175
D4: 東京都新宿区四谷4-1
AG6: 令和 | AI6: 7 | AL6: 年 | AM6: 7 | AO6: 月 | AP6: 17 | AR6: 日
D7: 大塚刷毛製造株式会社 | T7: 様
D11: 期日 | H11: 45948
D13: 場所 | H13: 城東営業所 | AB13: 振込先： | AE13: 十六銀行 柳ヶ瀬支店 普通：0777577
D15: 現金支払 | I15: 末締め末現金払い | AB15: 名義： | AE15: ｶ)ﾘﾝｼｭﾝﾄﾞｳ
AB17: 担当者 | AF17: 田中 健吾
J19: =H39 -> 96250
D20: 税込合計 | J20: =H39 -> 96250
B22: 見積書有効期限発効後60日
B24: 品 名 | T24: 数 量 | AA24: 税別単価 | AF24: 金 額 | AM24: 備 考
B26: 展示会参加諸経費 10/17金曜 10/18土曜 | AF26: =IF(T26="",1*AA26,T26*AA26) -> 0 | AM26: 城東営業所
B27: 公共交通費 往復 | X27: 一式 | AA27: 25000 | AF27: =IF(T27="",1*AA27,T27*AA27) -> 25000
B28: 宿泊費 1泊2日 1名分 | T28: 1 | X28: 一式 | AA28: 15000 | AF28: =IF(T28="",1*AA28,T28*AA28) -> 15000
B29: 日当１日1名分 10/17平日 | T29: 1 | X29: 一式 | AA29: 50000 | AF29: =IF(T29="",1*AA29,T29*AA29) -> 50000
B30: 日当１日1名分 10/18土日 | T30: 1 | X30: 一式 | AA30: 75000 | AF30: =IF(T30="",1*AA30,T30*AA30) -> 75000
B31: 展示会参加デモ用消耗品費 事前送付 | X31: 一式 | AA31: 10000 | AF31: =IF(T31="",1*AA31,T31*AA31) -> 10000
AF32: =IF(T32="",1*AA32,T32*AA32) -> 0
AF33: =IF(T33="",1*AA33,T33*AA33) -> 0
AF34: =IF(T34="",1*AA34,T34*AA34) -> 0
B35: 出展協力50％値引き | X35: 一式 | AA35: -87500 | AF35: =IF(T35="",1*AA35,T35*AA35) -> -87500
B36: 電源 遮光パネル 窒素 本体一式 御社手配 | X36: 一式 | AF36: =IF(T36="",1*AA36,T36*AA36) -> 0
AF37: =IF(T37="",1*AA37,T37*AA37) -> 0
B38: 消費税10% | H38: =AA38*0.1 -> 8750 | T38: 小 計 | AA38: =SUM(AF26:AL37) -> 87500
B39: 合計金額 | H39: =CK115+H38 -> 96250
B40: 摘要：
B41: 城東営業所 〒121-0064 東京都足立区保木間１丁目３−１２
P56: =SUM(CK115:CQ115) -> 87500
FB100: NO | FC100: 明細NO | FD100: 品名 | FE100: 数量 | FF100: 単位 | FG100: 単位 | FH100: 金額 | FI100: 備考
FB101: 0 | FC101: 1 | FD101: =B26 -> 展示会参加諸経費 10/17金曜 10/18土曜 | FE101: =T26 -> 0 | FF101: =X26 -> 0 | FG101: =AA26 -> 0 | FH101: =AF26 -> 0 | FI101: =AM26 -> 城東営業所
EM102: ON | FB102: 0 | FC102: 2 | FD102: =B27 -> 公共交通費 往復 | FE102: =T27 -> 0 | FF102: =X27 -> 一式 | FG102: =AA27 -> 25000 | FH102: =AF27 -> 25000 | FI102: =AM27 -> 0
CE103: 制御 | CI103: 総計 | CS103: 単位 | CW103: 消費税 | DD103: タイトル | DM103: ﾏｽﾀﾊﾞｯｸｱｯﾌﾟ | EM103: OFF | FB103: 0 | FC103: 3 | FD103: =B28 -> 宿泊費 1泊2日 1名分 | FE103: =T28 -> 1 | FF103: =X28 -> 一式 | FG103: =AA28 -> 15000 | FH103: =AF28 -> 15000 | FI103: =AM28 -> 0
CE104: 3 | CI104: 0 | CK104: =AA38 -> 87500 | CS104: 台 | CW104: 5 | CY104: ％ | DD104: 御 見 積 書 | DM104: ON | FB104: 0 | FC104: 4 | FD104: =B29 -> 日当１日1名分 10/17平日 | FE104: =T29 -> 1 | FF104: =X29 -> 一式 | FG104: =AA29 -> 50000 | FH104: =AF29 -> 50000 | FI104: =AM29 -> 0
CE105: =MAX(FB401:FB642) -> 0 | CI105: 1 | CK105: =IF(ISERROR(#REF!),0,#REF!) -> 0 | CS105: 個 | DD105: 納 品 書 | FB105: 0 | FC105: 5 | FD105: =#REF! -> #REF! | FE105: =T30 -> 1 | FF105: =X30 -> 一式 | FG105: =AA30 -> 75000 | FH105: =AF30 -> 75000 | FI105: =AM30 -> 0
CE106: 1 | CI106: 2 | CK106: =IF(ISERROR(#REF!),0,#REF!) -> 0 | CS106: 一式 | CV106: 画面表示 | DD106: 納 品 書 （控） | DM106: ﾃﾞｰﾀ保存ｼｰﾄ | FB106: 0 | FC106: 6 | FD106: =#REF! -> #REF! | FE106: =T31 -> 0 | FF106: =X31 -> 一式 | FG106: =AA31 -> 10000 | FH106: =AF31 -> 10000 | FI106: =AM31 -> 0
CE107: 0 | CI107: 3 | CK107: =IF(ISERROR(#REF!),0,#REF!) -> 0 | CS107: 冊 | CV107: ① | CW107: 100 | CZ107: ％ | DD107: 請 求 書 | DM107: データ保存 1.xls | FB107: 0 | FC107: 7 | FD107: =#REF! -> #REF! | FE107: =T32 -> 0 | FF107: =X32 -> 0 | FG107: =AA32 -> 0 | FH107: =AF32 -> 0 | FI107: =AM32 -> 0
CE108: 敬称 | CI108: 4 | CS108: 箱 | CV108: ② | CW108: 80 | CZ108: ％ | DD108: 請 求 書 （控） | DM108: 鑑 | FB108: 0 | FC108: 8 | FD108: =B31 -> 展示会参加デモ用消耗品費 事前送付 | FE108: =T33 -> 0 | FF108: =X33 -> 0 | FG108: =AA33 -> 0 | FH108: =AF33 -> 0 | FI108: =AM33 -> 0
CE109: 御中 | CI109: 5 | CS109: C/S | DM109: 明細 | FB109: 0 | FC109: 9 | FD109: =B34 -> 0 | FE109: =T34 -> 0 | FF109: =X34 -> 0 | FG109: =AA34 -> 0 | FH109: =AF34 -> 0 | FI109: =AM34 -> 0
...

Sheet フジペックス栃木営業所
M2: CODE | AA2: 御 見 積 書
E3: 〒160-8511 | AL3: No. | AN3: FL2507186
D4: 東京都新宿区四谷4-1
AG6: 令和 | AI6: 7 | AL6: 年 | AM6: 7 | AO6: 月 | AP6: 18 | AR6: 日
D7: 大塚刷毛製造株式会社 | T7: 様
D11: 期日 | H11: 2025/9/6-7
D13: 場所 | H13: 群馬県太田市吉沢町1058-5 | AB13: 振込先： | AE13: 十六銀行 柳ヶ瀬支店 普通：0777577
D15: 現金支払 | I15: 末締め末現金払い | AB15: 名義： | AE15: ｶ)ﾘﾝｼｭﾝﾄﾞｳ
AB17: 担当者 | AF17: 田中 健吾
J19: =H39 -> 220000
D20: 税込合計 | J20: =H39 -> 220000
B24: 品 名 | T24: 数 量 | AA24: 税別単価 | AF24: 金 額 | AM24: 備 考
B26: RSD-SUNMAX-FL-LCW-PRO 講習会 | AF26: =IF(T26="",1*AA26,T26*AA26) -> 0
B27: 交通費 往復 岐阜-太田市 商用車使用 | X27: 一式 | AA27: 50000 | AF27: =IF(T27="",1*AA27,T27*AA27) -> 50000
B28: ETC利用料金 | X28: 一式 | AA28: 19400 | AF28: =IF(T28="",1*AA28,T28*AA28) -> 19400
B29: 宿泊費 1泊2日 2名分 | X29: 一式 | AA29: 30000 | AF29: =IF(T29="",1*AA29,T29*AA29) -> 30000
B30: 日当１日1名分 土日 | T30: 4 | X30: 一式 | AA30: 75000 | AF30: =IF(T30="",1*AA30,T30*AA30) -> 300000
B31: FL-LCW デモ機展示設置費用LCW1.5kw | X31: 一式 | AA31: 20000 | AF31: =IF(T31="",1*AA31,T31*AA31) -> 20000
B32: 展示会参加デモ用消耗品費 | X32: 一式 | AA32: 15000 | AF32: =IF(T32="",1*AA32,T32*AA32) -> 15000
B33: 保護メガネ５人分程度、手袋、溶接台 弊社手配 | X33: 一式 | AA33: 10000 | AF33: =IF(T33="",1*AA33,T33*AA33) -> 10000
B34: 追加値引き | X34: 一式 | AA34: -22200 | AF34: =IF(T34="",1*AA34,T34*AA34) -> -22200
B35: 出展協力50％値引き | X35: 一式 | AA35: -222200 | AF35: =IF(T35="",1*AA35,T35*AA35) -> -222200
B36: 電源 遮光パネル 窒素 御社手配 | AF36: =IF(T36="",1*AA36,T36*AA36) -> 0
B37: デモ機の搬入撤収時男性お手伝い要します。 | AF37: =IF(T37="",1*AA37,T37*AA37) -> 0
B38: 消費税10% | H38: =AA38*0.1 -> 20000 | T38: 小 計 | AA38: =SUM(AF26:AL37) -> 200000
B39: 合計金額 | H39: =CK115+H38 -> 220000
B40: 摘要： | E40: 発注書No2489059
B41: 場所 株式会社フジペックス栃木営業所 栃木県下野市下石橋148-4
P56: =SUM(CK115:CQ115) -> 200000
FB100: NO | FC100: 明細NO | FD100: 品名 | FE100: 数量 | FF100: 単位 | FG100: 単位 | FH100: 金額 | FI100: 備考
FB101: 0 | FC101: 1 | FD101: =B26 -> RSD-SUNMAX-FL-LCW-PRO 講習会 | FE101: =T26 -> 0 | FF101: =X26 -> 0 | FG101: =AA26 -> 0 | FH101: =AF26 -> 0 | FI101: =AM26 -> 0
EM102: ON | FB102: 0 | FC102: 2 | FD102: =B27 -> 交通費 往復 岐阜-太田市 商用車使用 | FE102: =T27 -> 0 | FF102: =X27 -> 一式 | FG102: =AA27 -> 50000 | FH102: =AF27 -> 50000 | FI102: =AM27 -> 0
CE103: 制御 | CI103: 総計 | CS103: 単位 | CW103: 消費税 | DD103: タイトル | DM103: ﾏｽﾀﾊﾞｯｸｱｯﾌﾟ | EM103: OFF | FB103: 0 | FC103: 3 | FD103: =B28 -> ETC利用料金 | FE103: =T28 -> 0 | FF103: =X28 -> 一式 | FG103: =AA28 -> 19400 | FH103: =AF28 -> 19400 | FI103: =AM28 -> 0
CE104: 3 | CI104: 0 | CK104: =AA38 -> 200000 | CS104: 台 | CW104: 5 | CY104: ％ | DD104: 御 見 積 書 | DM104: ON | FB104: 0 | FC104: 4 | FD104: =B29 -> 宿泊費 1泊2日 2名分 | FE104: =T29 -> 0 | FF104: =X29 -> 一式 | FG104: =AA29 -> 30000 | FH104: =AF29 -> 30000 | FI104: =AM29 -> 0
CE105: =MAX(FB401:FB642) -> 0 | CI105: 1 | CK105: =IF(ISERROR(#REF!),0,#REF!) -> 0 | CS105: 個 | DD105: 納 品 書 | FB105: 0 | FC105: 5 | FD105: =#REF! -> #REF! | FE105: =T30 -> 4 | FF105: =X30 -> 一式 | FG105: =AA30 -> 75000 | FH105: =AF30 -> 300000 | FI105: =AM30 -> 0
CE106: 1 | CI106: 2 | CK106: =IF(ISERROR(#REF!),0,#REF!) -> 0 | CS106: 一式 | CV106: 画面表示 | DD106: 納 品 書 （控） | DM106: ﾃﾞｰﾀ保存ｼｰﾄ | FB106: 0 | FC106: 6 | FD106: =#REF! -> #REF! | FE106: =T31 -> 0 | FF106: =X31 -> 一式 | FG106: =AA31 -> 20000 | FH106: =AF31 -> 20000 | FI106: =AM31 -> 0
CE107: 0 | CI107: 3 | CK107: =IF(ISERROR(#REF!),0,#REF!) -> 0 | CS107: 冊 | CV107: ① | CW107: 100 | CZ107: ％ | DD107: 請 求 書 | DM107: データ保存 1.xls | FB107: 0 | FC107: 7 | FD107: =#REF! -> #REF! | FE107: =T32 -> 0 | FF107: =X32 -> 一式 | FG107: =AA32 -> 15000 | FH107: =AF32 -> 15000 | FI107: =AM32 -> 0
CE108: 敬称 | CI108: 4 | CS108: 箱 | CV108: ② | CW108: 80 | CZ108: ％ | DD108: 請 求 書 （控） | DM108: 鑑 | FB108: 0 | FC108: 8 | FD108: =B31 -> FL-LCW デモ機展示設置費用LCW1.5kw | FE108: =T33 -> 0 | FF108: =X33 -> 一式 | FG108: =AA33 -> 10000 | FH108: =AF33 -> 10000 | FI108: =AM33 -> 0
CE109: 御中 | CI109: 5 | CS109: C/S | DM109: 明細 | FB109: 0 | FC109: 9 | FD109: =B34 -> 追加値引き | FE109: =T34 -> 0 | FF109: =X34 -> 一式 | FG109: =AA34 -> -22200 | FH109: =AF34 -> -22200 | FI109: =AM34 -> 0
CE110: 様 | CI110: 6 | CS110: SET | CV110: 画像ファイル名 | DE110: 画像名 | FB110: 0 | FC110: 10 | FD110: =B35 -> 出展協力50％値引き | FE110: =T35 -> 0 | FF110: =X35 -> 一式 | FG110: =AA35 -> -222200 | FH110: =AF35 -> -222200 | FI110: =AM35 -> 0
...

Sheet 展示会準備項目
D3: 一覧 | AL3: No.
C5: 準備 品 名 | U5: 数 量 | AB5: 単 価 | AG5: 金 額 | AN5: 備 考
C7: 遮光パネル／保護カーテン | U7: 1 | AG7: =IF(U7="",1*AB7,U7*AB7) -> 0 | AN7: 弊社準備
C8: 三相200V 30A ストレートタイプコンセント | U8: 1 | AG8: =IF(U8="",1*AB8,U8*AB8) -> 0 | AN8: 御社準備
C9: 100ｖ 10Aコンセント | U9: 1 | AG9: =IF(U9="",1*AB9,U9*AB9) -> 0 | AN9: 御社準備
B10: 1日1本目安 | C10: 会期中窒素ボンベ(1日1本目安) | U10: 2 | AG10: =IF(U10="",1*AB10,U10*AB10) -> 0 | AN10: 弊社準備
C11: 錆び取り洗浄用デモ実演用素材 | U11: 1 | AG11: =IF(U11="",1*AB11,U11*AB11) -> 0 | AN11: 弊社準備
B12: 自動車外板パネル等 | C12: 溶接ワーク(溶接素材、自動車外板パネル等) | U12: 1 | AG12: =IF(U12="",1*AB12,U12*AB12) -> 0 | AN12: 弊社準備
C13: 展示用の机 | U13: 1 | AG13: =IF(U13="",1*AB13,U13*AB13) -> 0 | AN13: 弊社準備
C14: 溶接机 1台 溶接サンプル | U14: 1 | AG14: =IF(U14="",1*AB14,U14*AB14) -> 0 | AN14: 弊社準備
AG15: =IF(U15="",1*AB15,U15*AB15) -> 0
AG16: =IF(U16="",1*AB16,U16*AB16) -> 0
AG17: =IF(U17="",1*AB17,U17*AB17) -> 0
AG18: =IF(U18="",1*AB18,U18*AB18) -> 0
AG19: =IF(U19="",1*AB19,U19*AB19) -> 0
AG20: =IF(U20="",1*AB20,U20*AB20) -> 0
AG21: =IF(U21="",1*AB21,U21*AB21) -> 0
AG22: =IF(U22="",1*AB22,U22*AB22) -> 0
C23: ボンデ鋼板 2.3t 100x50 | U23: 10 | AB23: 300 | AG23: =IF(U23="",1*AB23,U23*AB23) -> 3000
C24: ZAM材 2.3t 100x50 | U24: 10 | AB24: 350 | AG24: =IF(U24="",1*AB24,U24*AB24) -> 3500
C25: ステンレス 2t 100x50 | U25: 8 | AB25: 400 | AG25: =IF(U25="",1*AB25,U25*AB25) -> 3200
C26: アルミ 2t 100x50 | U26: 8 | AB26: 600 | AG26: =IF(U26="",1*AB26,U26*AB26) -> 4800
C27: 自動車外板パネル 0.8/0/6t | U27: 1 | AB27: 3000 | AG27: =IF(U27="",1*AB27,U27*AB27) -> 3000
AG28: =IF(U28="",1*AB28,U28*AB28) -> 0
B29: FAX感熱紙(A4) | AG29: =IF(U29="",1*AB29,U29*AB29) -> 0
U30: 小 計 | AB30: =SUM(AG7:AG29) -> 17500
CS103: 単位
CS104: =#REF! -> #REF!
CS105: =#REF! -> #REF!
CS106: =#REF! -> #REF!
CS107: =#REF! -> #REF!
CS108: =#REF! -> #REF!
CS109: =#REF! -> #REF!
CS110: =#REF! -> #REF!
CS111: =#REF! -> #REF!
CS112: =#REF! -> #REF!
CS113: =#REF! -> #REF!
CS114: =#REF! -> #REF!
CS115: =#REF! -> #REF!
CS116: =#REF! -> #REF!
...

Sheet デモ材料費
M2: CODE | AA2: 御 見 積 書
E3: 108-0023 | AL3: No. | AN3: FL2504225
D4: 東京都港区芝浦４－１６－２５
AG6: 令和 | AI6: 7 | AL6: 年 | AM6: 4 | AO6: 月 | AP6: 22 | AR6: 日
D7: 安全自動車株式会社 | T7: 様
D11: 受渡期日 | H11: 展示会開催
D13: 受渡場所 | H13: 東京ビッグサイト | AB13: 振込先： | AE13: 十六銀行 柳ヶ瀬支店 普通：0777577
D15: 現金支払 | I15: 末締め末現金払い | AB15: 名義： | AE15: ｶ)ﾘﾝｼｭﾝﾄﾞｳ
AB17: 担当者 | AF17: 田中 健吾
J19: =H39 -> 39820
D20: 税込合計 | J20: =H39 -> 39820
B22: 見積書有効期限発効後1年
B24: 品 名 | T24: 数 量 | AA24: 税別単価 | AF24: 金 額 | AM24: 備 考
B26: 東京ビッグサイト展示会 | AF26: =IF(T26="",1*AA26,T26*AA26) -> 0
B27: 溶接テスト用材料費 アルミ ステンレス 鉄 | X27: 一式 | AA27: 35000 | AF27: =IF(T27="",1*AA27,T27*AA27) -> 35000
B28: 送料 事前送付 | X28: 一式 | AA28: 1200 | AF28: =IF(T28="",1*AA28,T28*AA28) -> 1200
AF29: =IF(T29="",1*AA29,T29*AA29) -> 0
AF30: =IF(T30="",1*AA30,T30*AA30) -> 0
AF31: =IF(T31="",1*AA31,T31*AA31) -> 0
AF32: =IF(T32="",1*AA32,T32*AA32) -> 0
AF33: =IF(T33="",1*AA33,T33*AA33) -> 0
AF34: =IF(T34="",1*AA34,T34*AA34) -> 0
AF35: =IF(T35="",1*AA35,T35*AA35) -> 0
B38: 消費税10% | H38: =AA38*0.1 -> 3620 | T38: 小 計 | AA38: =SUM(AF26:AL37) -> 36200
B39: 合計金額 | H39: =CK115+H38 -> 39820
B40: 摘要：
P56: =SUM(CK115:CQ115) -> 36200
FB100: NO | FC100: 明細NO | FD100: 品名 | FE100: 数量 | FF100: 単位 | FG100: 単位 | FH100: 金額 | FI100: 備考
FB101: 0 | FC101: 1 | FD101: =B26 -> 東京ビッグサイト展示会 | FE101: =T26 -> 0 | FF101: =X26 -> 0 | FG101: =AA26 -> 0 | FH101: =AF26 -> 0 | FI101: =AM26 -> 0
EM102: ON | FB102: 0 | FC102: 2 | FD102: =B27 -> 溶接テスト用材料費 アルミ ステンレス 鉄 | FE102: =T27 -> 0 | FF102: =X27 -> 一式 | FG102: =AA27 -> 35000 | FH102: =AF27 -> 35000 | FI102: =AM27 -> 0
CE103: 制御 | CI103: 総計 | CS103: 単位 | CW103: 消費税 | DD103: タイトル | DM103: ﾏｽﾀﾊﾞｯｸｱｯﾌﾟ | EM103: OFF | FB103: 0 | FC103: 3 | FD103: =B28 -> 送料 事前送付 | FE103: =T28 -> 0 | FF103: =X28 -> 一式 | FG103: =AA28 -> 1200 | FH103: =AF28 -> 1200 | FI103: =AM28 -> 0
CE104: 3 | CI104: 0 | CK104: =AA38 -> 36200 | CS104: 台 | CW104: 5 | CY104: ％ | DD104: 御 見 積 書 | DM104: ON | FB104: 0 | FC104: 4 | FD104: =B29 -> 0 | FE104: =T29 -> 0 | FF104: =X29 -> 0 | FG104: =AA29 -> 0 | FH104: =AF29 -> 0 | FI104: =AM29 -> 0
CE105: =MAX(FB401:FB642) -> 0 | CI105: 1 | CK105: =IF(ISERROR([1]本体装備品一覧!AB30),0,[1]本体装備品一覧!AB30) -> 0 | CS105: 個 | DD105: 納 品 書 | FB105: 0 | FC105: 5 | FD105: =#REF! -> #REF! | FE105: =T30 -> 0 | FF105: =X30 -> 0 | FG105: =AA30 -> 0 | FH105: =AF30 -> 0 | FI105: =AM30 -> 0
CE106: 1 | CI106: 2 | CK106: =IF(ISERROR(#REF!),0,#REF!) -> 0 | CS106: 一式 | CV106: 画面表示 | DD106: 納 品 書 （控） | DM106: ﾃﾞｰﾀ保存ｼｰﾄ | FB106: 0 | FC106: 6 | FD106: =#REF! -> #REF! | FE106: =T31 -> 0 | FF106: =X31 -> 0 | FG106: =AA31 -> 0 | FH106: =AF31 -> 0 | FI106: =AM31 -> 0
CE107: 0 | CI107: 3 | CK107: =IF(ISERROR(#REF!),0,#REF!) -> 0 | CS107: 冊 | CV107: ① | CW107: 100 | CZ107: ％ | DD107: 請 求 書 | DM107: データ保存 1.xls | FB107: 0 | FC107: 7 | FD107: =#REF! -> #REF! | FE107: =T32 -> 0 | FF107: =X32 -> 0 | FG107: =AA32 -> 0 | FH107: =AF32 -> 0 | FI107: =AM32 -> 0
CE108: 敬称 | CI108: 4 | CS108: 箱 | CV108: ② | CW108: 80 | CZ108: ％ | DD108: 請 求 書 （控） | DM108: 鑑 | FB108: 0 | FC108: 8 | FD108: =B31 -> 0 | FE108: =T33 -> 0 | FF108: =X33 -> 0 | FG108: =AA33 -> 0 | FH108: =AF33 -> 0 | FI108: =AM33 -> 0
CE109: 御中 | CI109: 5 | CS109: C/S | DM109: 明細 | FB109: 0 | FC109: 9 | FD109: =B34 -> 0 | FE109: =T34 -> 0 | FF109: =X34 -> 0 | FG109: =AA34 -> 0 | FH109: =AF34 -> 0 | FI109: =AM34 -> 0
CE110: 様 | CI110: 6 | CS110: SET | CV110: 画像ファイル名 | DE110: 画像名 | FB110: 0 | FC110: 10 | FD110: =B35 -> 0 | FE110: =T35 -> 0 | FF110: =X35 -> 0 | FG110: =AA35 -> 0 | FH110: =AF35 -> 0 | FI110: =AM35 -> 0
CE111: 殿 | CI111: 7 | CS111: 本 | CV111: ① | CW111: 会社角印.gif | DE111: 会社角印 | FB111: 0 | FC111: 11 | FD111: =B36 -> 0 | FE111: =T36 -> 0 | FF111: =X36 -> 0 | FG111: =AA36 -> 0 | FH111: =AF36 -> 0 | FI111: =AM36 -> 0
CI112: 8 | CS112: 束 | CV112: ② | CW112: 林印.png | DE112: 林印 | FB112: 0 | FC112: 12 | FD112: =B37 -> 0 | FE112: =T37 -> 0 | FF112: =X37 -> 0 | FG112: =AA37 -> 0 | FH112: =AF37 -> 0 | FI112: =AM37 -> 0
...
