Workbook

Sheet 見積書A4
M2: CODE | AA2: 御 見 積 書
E3: 160-8511 | AL3: No. | AN3: FL2412245
D4: 東京都新宿区四谷4-1
AG6: 令和 | AI6: 6 | AL6: 年 | AM6: 12 | AO6: 月 | AP6: 24 | AR6: 日
D7: 大塚刷毛製造株式会社 | T7: 様
D11: 受渡期日 | H11: 14日～機種により
D13: 受渡場所 | H13: 貴社指定場所 | AB13: 振込先： | AE13: 十六銀行 柳ヶ瀬支店 普通：0777577
D15: 現金支払 | I15: 末締め末現金払い | AB15: 名義： | AE15: ｶ)ﾘﾝｼｭﾝﾄﾞｳ
AB17: 担当者 | AF17: 田中 健吾
J19: =H39 -> 165000
D20: 税込合計 | J20: =H39 -> 165000
B22: 見積書有効期限発効後1年
B24: 品 名 | T24: 数 量 | AA24: 税別単価 | AF24: 金 額 | AM24: 備 考
B26: RSD-SUNMAX-FL-LCW 1500w | X26: 一式 | AF26: =IF(T26="",1*AA26,T26*AA26) -> 0
B27: 設置操作講習費 日時：2025年4月12日（土曜） | X27: 一式 | AA27: 150000 | AF27: =IF(T27="",1*AA27,T27*AA27) -> 150000 | AM27: 10:00～17:00
AF28: =IF(T28="",1*AA28,T28*AA28) -> 0
B29: デモ機持ち込み費用除く | AF29: =IF(T29="",1*AA29,T29*AA29) -> 0
AF30: =IF(T30="",1*AA30,T30*AA30) -> 0
AF31: =IF(T31="",1*AA31,T31*AA31) -> 0
AF32: =IF(T32="",1*AA32,T32*AA32) -> 0
AF33: =IF(T33="",1*AA33,T33*AA33) -> 0
AF34: =IF(T34="",1*AA34,T34*AA34) -> 0
AF35: =IF(T35="",1*AA35,T35*AA35) -> 0
H38: =AA38*0.1 -> 15000 | T38: 小 計 | AA38: =SUM(AF26:AL37) -> 150000
B39: 合計金額 | H39: =CK115+H38 -> 165000
B40: 摘要： | E40: 場所 大塚刷毛製造株式会社 茨城営業所
B41: 〒300-0066 茨城県土浦市虫掛3545
P56: =SUM(CK115:CQ115) -> 150000
FB100: NO | FC100: 明細NO | FD100: 品名 | FE100: 数量 | FF100: 単位 | FG100: 単位 | FH100: 金額 | FI100: 備考
FB101: 0 | FC101: 1 | FD101: =B26 -> RSD-SUNMAX-FL-LCW 1500w | FE101: =T26 -> 0 | FF101: =X26 -> 一式 | FG101: =AA26 -> 0 | FH101: =AF26 -> 0 | FI101: =AM26 -> 0
EM102: ON | FB102: 0 | FC102: 2 | FD102: =B27 -> 設置操作講習費 日時：2025年4月12日（土曜） | FE102: =T27 -> 0 | FF102: =X27 -> 一式 | FG102: =AA27 -> 150000 | FH102: =AF27 -> 150000 | FI102: =AM27 -> 10:00～17:00
CE103: 制御 | CI103: 総計 | CS103: 単位 | CW103: 消費税 | DD103: タイトル | DM103: ﾏｽﾀﾊﾞｯｸｱｯﾌﾟ | EM103: OFF | FB103: 0 | FC103: 3 | FD103: =B28 -> 0 | FE103: =T28 -> 0 | FF103: =X28 -> 0 | FG103: =AA28 -> 0 | FH103: =AF28 -> 0 | FI103: =AM28 -> 0
CE104: 3 | CI104: 0 | CK104: =AA38 -> 150000 | CS104: 台 | CW104: 5 | CY104: ％ | DD104: 御 見 積 書 | DM104: ON | FB104: 0 | FC104: 4 | FD104: =B29 -> デモ機持ち込み費用除く | FE104: =T29 -> 0 | FF104: =X29 -> 0 | FG104: =AA29 -> 0 | FH104: =AF29 -> 0 | FI104: =AM29 -> 0
CE105: =MAX(FB401:FB642) -> 0 | CI105: 1 | CK105: =IF(ISERROR(本体装備品一覧!AB30),0,本体装備品一覧!AB30) -> 0 | CS105: 個 | DD105: 納 品 書 | FB105: 0 | FC105: 5 | FD105: =#REF! -> #REF! | FE105: =T30 -> 0 | FF105: =X30 -> 0 | FG105: =AA30 -> 0 | FH105: =AF30 -> 0 | FI105: =AM30 -> 0
CE106: 1 | CI106: 2 | CK106: =IF(ISERROR(#REF!),0,#REF!) -> 0 | CS106: 一式 | CV106: 画面表示 | DD106: 納 品 書 （控） | DM106: ﾃﾞｰﾀ保存ｼｰﾄ | FB106: 0 | FC106: 6 | FD106: =#REF! -> #REF! | FE106: =T31 -> 0 | FF106: =X31 -> 0 | FG106: =AA31 -> 0 | FH106: =AF31 -> 0 | FI106: =AM31 -> 0
CE107: 0 | CI107: 3 | CK107: =IF(ISERROR(#REF!),0,#REF!) -> 0 | CS107: 冊 | CV107: ① | CW107: 100 | CZ107: ％ | DD107: 請 求 書 | DM107: データ保存 1.xls | FB107: 0 | FC107: 7 | FD107: =#REF! -> #REF! | FE107: =T32 -> 0 | FF107: =X32 -> 0 | FG107: =AA32 -> 0 | FH107: =AF32 -> 0 | FI107: =AM32 -> 0
CE108: 敬称 | CI108: 4 | CS108: 箱 | CV108: ② | CW108: 80 | CZ108: ％ | DD108: 請 求 書 （控） | DM108: 鑑 | FB108: 0 | FC108: 8 | FD108: =B31 -> 0 | FE108: =T33 -> 0 | FF108: =X33 -> 0 | FG108: =AA33 -> 0 | FH108: =AF33 -> 0 | FI108: =AM33 -> 0
CE109: 御中 | CI109: 5 | CS109: C/S | DM109: 明細 | FB109: 0 | FC109: 9 | FD109: =B34 -> 0 | FE109: =T34 -> 0 | FF109: =X34 -> 0 | FG109: =AA34 -> 0 | FH109: =AF34 -> 0 | FI109: =AM34 -> 0
CE110: 様 | CI110: 6 | CS110: SET | CV110: 画像ファイル名 | DE110: 画像名 | FB110: 0 | FC110: 10 | FD110: =B35 -> 0 | FE110: =T35 -> 0 | FF110: =X35 -> 0 | FG110: =AA35 -> 0 | FH110: =AF35 -> 0 | FI110: =AM35 -> 0
CE111: 殿 | CI111: 7 | CS111: 本 | CV111: ① | CW111: 会社角印.gif | DE111: 会社角印 | FB111: 0 | FC111: 11 | FD111: =B36 -> 0 | FE111: =T36 -> 0 | FF111: =X36 -> 0 | FG111: =AA36 -> 0 | FH111: =AF36 -> 0 | FI111: =AM36 -> 0
...

Sheet 請求書
M2: CODE | AA2: 請 求 書
E3: 160-8511 | AL3: No. | AN3: FL2504145
D4: 東京都新宿区四谷4-1
AG6: 令和 | AI6: 7 | AL6: 年 | AM6: 4 | AO6: 月 | AP6: 14 | AR6: 日
D7: 大塚刷毛製造株式会社 | T7: 様
D11: 受渡期日 | H11: 45759
D13: 受渡場所 | H13: 茨城営業所 | AB13: 振込先： | AE13: 十六銀行 柳ヶ瀬支店 普通：0777577
D15: 現金支払 | I15: 末締め末現金払い | AB15: 名義： | AE15: ｶ)ﾘﾝｼｭﾝﾄﾞｳ
AB17: 担当者 | AF17: 田中 健吾
J19: =H39 -> 165000
D20: 税込合計 | J20: =H39 -> 165000
B22: 見積書有効期限発効後1年
B24: 品 名 | T24: 数 量 | AA24: 税別単価 | AF24: 金 額 | AM24: 備 考
B26: RSD-SUNMAX-FL-LCW 1500w | X26: 一式 | AF26: =IF(T26="",1*AA26,T26*AA26) -> 0
B27: 設置操作講習費 日時：2025年4月12日（土曜） | X27: 一式 | AA27: 150000 | AF27: =IF(T27="",1*AA27,T27*AA27) -> 150000 | AM27: 10:00～17:00
AF28: =IF(T28="",1*AA28,T28*AA28) -> 0
B29: デモ機持ち込み費用除く | AF29: =IF(T29="",1*AA29,T29*AA29) -> 0
AF30: =IF(T30="",1*AA30,T30*AA30) -> 0
AF31: =IF(T31="",1*AA31,T31*AA31) -> 0
AF32: =IF(T32="",1*AA32,T32*AA32) -> 0
AF33: =IF(T33="",1*AA33,T33*AA33) -> 0
AF34: =IF(T34="",1*AA34,T34*AA34) -> 0
AF35: =IF(T35="",1*AA35,T35*AA35) -> 0
H38: =AA38*0.1 -> 15000 | T38: 小 計 | AA38: =SUM(AF26:AL37) -> 150000
B39: 合計金額 | H39: =CK115+H38 -> 165000
B40: 摘要： | E40: 場所 大塚刷毛製造株式会社 茨城営業所
B41: 〒300-0066 茨城県土浦市虫掛3545
P56: =SUM(CK115:CQ115) -> 150000
FB100: NO | FC100: 明細NO | FD100: 品名 | FE100: 数量 | FF100: 単位 | FG100: 単位 | FH100: 金額 | FI100: 備考
FB101: 0 | FC101: 1 | FD101: =B26 -> RSD-SUNMAX-FL-LCW 1500w | FE101: =T26 -> 0 | FF101: =X26 -> 一式 | FG101: =AA26 -> 0 | FH101: =AF26 -> 0 | FI101: =AM26 -> 0
EM102: ON | FB102: 0 | FC102: 2 | FD102: =B27 -> 設置操作講習費 日時：2025年4月12日（土曜） | FE102: =T27 -> 0 | FF102: =X27 -> 一式 | FG102: =AA27 -> 150000 | FH102: =AF27 -> 150000 | FI102: =AM27 -> 10:00～17:00
CE103: 制御 | CI103: 総計 | CS103: 単位 | CW103: 消費税 | DD103: タイトル | DM103: ﾏｽﾀﾊﾞｯｸｱｯﾌﾟ | EM103: OFF | FB103: 0 | FC103: 3 | FD103: =B28 -> 0 | FE103: =T28 -> 0 | FF103: =X28 -> 0 | FG103: =AA28 -> 0 | FH103: =AF28 -> 0 | FI103: =AM28 -> 0
CE104: 3 | CI104: 0 | CK104: =AA38 -> 150000 | CS104: 台 | CW104: 5 | CY104: ％ | DD104: 御 見 積 書 | DM104: ON | FB104: 0 | FC104: 4 | FD104: =B29 -> デモ機持ち込み費用除く | FE104: =T29 -> 0 | FF104: =X29 -> 0 | FG104: =AA29 -> 0 | FH104: =AF29 -> 0 | FI104: =AM29 -> 0
CE105: =MAX(FB401:FB642) -> 0 | CI105: 1 | CK105: =IF(ISERROR(本体装備品一覧!AB30),0,本体装備品一覧!AB30) -> 0 | CS105: 個 | DD105: 納 品 書 | FB105: 0 | FC105: 5 | FD105: =#REF! -> #REF! | FE105: =T30 -> 0 | FF105: =X30 -> 0 | FG105: =AA30 -> 0 | FH105: =AF30 -> 0 | FI105: =AM30 -> 0
CE106: 1 | CI106: 2 | CK106: =IF(ISERROR(#REF!),0,#REF!) -> 0 | CS106: 一式 | CV106: 画面表示 | DD106: 納 品 書 （控） | DM106: ﾃﾞｰﾀ保存ｼｰﾄ | FB106: 0 | FC106: 6 | FD106: =#REF! -> #REF! | FE106: =T31 -> 0 | FF106: =X31 -> 0 | FG106: =AA31 -> 0 | FH106: =AF31 -> 0 | FI106: =AM31 -> 0
CE107: 0 | CI107: 3 | CK107: =IF(ISERROR(#REF!),0,#REF!) -> 0 | CS107: 冊 | CV107: ① | CW107: 100 | CZ107: ％ | DD107: 請 求 書 | DM107: データ保存 1.xls | FB107: 0 | FC107: 7 | FD107: =#REF! -> #REF! | FE107: =T32 -> 0 | FF107: =X32 -> 0 | FG107: =AA32 -> 0 | FH107: =AF32 -> 0 | FI107: =AM32 -> 0
CE108: 敬称 | CI108: 4 | CS108: 箱 | CV108: ② | CW108: 80 | CZ108: ％ | DD108: 請 求 書 （控） | DM108: 鑑 | FB108: 0 | FC108: 8 | FD108: =B31 -> 0 | FE108: =T33 -> 0 | FF108: =X33 -> 0 | FG108: =AA33 -> 0 | FH108: =AF33 -> 0 | FI108: =AM33 -> 0
CE109: 御中 | CI109: 5 | CS109: C/S | DM109: 明細 | FB109: 0 | FC109: 9 | FD109: =B34 -> 0 | FE109: =T34 -> 0 | FF109: =X34 -> 0 | FG109: =AA34 -> 0 | FH109: =AF34 -> 0 | FI109: =AM34 -> 0
CE110: 様 | CI110: 6 | CS110: SET | CV110: 画像ファイル名 | DE110: 画像名 | FB110: 0 | FC110: 10 | FD110: =B35 -> 0 | FE110: =T35 -> 0 | FF110: =X35 -> 0 | FG110: =AA35 -> 0 | FH110: =AF35 -> 0 | FI110: =AM35 -> 0
CE111: 殿 | CI111: 7 | CS111: 本 | CV111: ① | CW111: 会社角印.gif | DE111: 会社角印 | FB111: 0 | FC111: 11 | FD111: =B36 -> 0 | FE111: =T36 -> 0 | FF111: =X36 -> 0 | FG111: =AA36 -> 0 | FH111: =AF36 -> 0 | FI111: =AM36 -> 0
...

Sheet 別紙購入おすすめ品
D3: 別紙購入おすすめ品一覧 | AL3: No.
C5: 付 属 品 名 | U5: 数 量 | AB5: 単 価 | AG5: 金 額 | AN5: 備 考
C7: 反射レンズレンズ＋ステー | U7: 1 | Y7: 枚 | AB7: 13200 | AG7: =IF(U7="",1*AB7,U7*AB7) -> 13200
C8: コリメーターレンズ | U8: 1 | Y8: 枚 | AB8: 10340 | AG8: =IF(U8="",1*AB8,U8*AB8) -> 10340
C9: 溶接・切断用焦点レンズ【ケース付き】 | U9: 1 | Y9: 枚 | AB9: 18400 | AG9: =IF(U9="",1*AB9,U9*AB9) -> 18400
C10: 洗浄用焦点レンズ【ケース付き】 | U10: 1 | Y10: 枚 | AB10: 18400 | AG10: =IF(U10="",1*AB10,U10*AB10) -> 18400
C11: シールリング ※シールリングのみ | U11: 1 | Y11: 枚 | AB11: 3960 | AG11: =IF(U11="",1*AB11,U11*AB11) -> 3960
C12: 溶接・切断用 保護レンズ | U12: 10 | Y12: 枚 | AB12: 1200 | AG12: =IF(U12="",1*AB12,U12*AB12) -> 12000
AG13: =IF(U13="",1*AB13,U13*AB13) -> 0
AG14: =IF(U14="",1*AB14,U14*AB14) -> 0
AG15: =IF(U15="",1*AB15,U15*AB15) -> 0
AG16: =IF(U16="",1*AB16,U16*AB16) -> 0
AG17: =IF(U17="",1*AB17,U17*AB17) -> 0
AG18: =IF(U18="",1*AB18,U18*AB18) -> 0
AG19: =IF(U19="",1*AB19,U19*AB19) -> 0
AG20: =IF(U20="",1*AB20,U20*AB20) -> 0
AG21: =IF(U21="",1*AB21,U21*AB21) -> 0
AG22: =IF(U22="",1*AB22,U22*AB22) -> 0
AG23: =IF(U23="",1*AB23,U23*AB23) -> 0
AG24: =IF(U24="",1*AB24,U24*AB24) -> 0
... AG28: =IF(U28="",1*AB28,U28*AB28) -> 0
B29: FAX感熱紙(A4) | AG29: =IF(U29="",1*AB29,U29*AB29) -> 0
U30: 小 計 | AB30: =SUM(AG7:AG29) -> 76300
CS103: 単位
CS104: =見積書A4!CS104 -> 台
CS105: =見積書A4!CS105 -> 個
CS106: =見積書A4!CS106 -> 一式
CS107: =見積書A4!CS107 -> 冊
CS108: =見積書A4!CS108 -> 箱
CS109: =見積書A4!CS109 -> C/S
CS110: =見積書A4!CS110 -> SET
CS111: =見積書A4!CS111 -> 本
CS112: =見積書A4!CS112 -> 束
CS113: =見積書A4!CS113 -> 枚
CS114: =見積書A4!CS114 -> ﾊﾟｯｸ
CS115: =見積書A4!CS115 -> ｷｯﾄ
CS116: =見積書A4!CS116 -> 0
CI119: マスタパス | CM119: =見積書A4!CM119 -> C:\Documents and Settings\sato\My Documents\シンプル見積書\ | DO119: =見積書A4!$DO$119 -> マスタ 1.xls
CI120: データパス | CM120: =見積書A4!CM120 -> 0
P178: =見積書A4!P177 -> 0

Sheet USBフラッシュメモリ内一覧
D3: USBフラッシュメモリ内一覧 | AL3: No.
C5: 付 属 品 名 | U5: 数 量 | AB5: 単 価 | AG5: 金 額 | AN5: 備 考
C7: User Manual_FL_LCW-3000W Ver.2.0 （取扱 説明書) | U7: 1 | Y7: SET | AG7: =IF(U7="",1*AB7,U7*AB7) -> 0
C8: 焦点レンズの清掃・交換 | U8: 1 | Y8: SET | AG8: =IF(U8="",1*AB8,U8*AB8) -> 0
C9: 保護レンズの清掃・交換 | U9: 1 | Y9: SET
C10: 溶接の設定出し | U10: 1 | Y10: SET | AG10: =IF(U10="",1*AB10,U10*AB10) -> 0
C11: LCW全機種設定表 | U11: 1 | Y11: SET | AG11: =IF(U11="",1*AB11,U11*AB11) -> 0
C12: 3000W設定表 | U12: 1 | Y12: SET | AG12: =IF(U12="",1*AB12,U12*AB12) -> 0
AG13: =IF(U13="",1*AB13,U13*AB13) -> 0
AG14: =IF(U14="",1*AB14,U14*AB14) -> 0
AG15: =IF(U15="",1*AB15,U15*AB15) -> 0
AG16: =IF(U16="",1*AB16,U16*AB16) -> 0
AG17: =IF(U17="",1*AB17,U17*AB17) -> 0
AG18: =IF(U18="",1*AB18,U18*AB18) -> 0
AG19: =IF(U19="",1*AB19,U19*AB19) -> 0
AG20: =IF(U20="",1*AB20,U20*AB20) -> 0
AG21: =IF(U21="",1*AB21,U21*AB21) -> 0
AG22: =IF(U22="",1*AB22,U22*AB22) -> 0
AG23: =IF(U23="",1*AB23,U23*AB23) -> 0
AG24: =IF(U24="",1*AB24,U24*AB24) -> 0
... AG28: =IF(U28="",1*AB28,U28*AB28) -> 0
B29: FAX感熱紙(A4) | AG29: =IF(U29="",1*AB29,U29*AB29) -> 0
U30: 小 計
CS103: 単位
CS104: =見積書A4!CS104 -> 台
CS105: =見積書A4!CS105 -> 個
CS106: =見積書A4!CS106 -> 一式
CS107: =見積書A4!CS107 -> 冊
CS108: =見積書A4!CS108 -> 箱
CS109: =見積書A4!CS109 -> C/S
CS110: =見積書A4!CS110 -> SET
CS111: =見積書A4!CS111 -> 本
CS112: =見積書A4!CS112 -> 束
CS113: =見積書A4!CS113 -> 枚
CS114: =見積書A4!CS114 -> ﾊﾟｯｸ
CS115: =見積書A4!CS115 -> ｷｯﾄ
CS116: =見積書A4!CS116 -> 0
CI119: マスタパス | CM119: =見積書A4!CM119 -> C:\Documents and Settings\sato\My Documents\シンプル見積書\ | DO119: =見積書A4!$DO$119 -> マスタ 1.xls
CI120: データパス | CM120: =見積書A4!CM120 -> 0
P178: =見積書A4!P177 -> 0

Sheet 工具箱内付属一覧
D3: 工具箱内付属一覧 | AL3: No.
C5: 付 属 品 名 | U5: 数 量 | AB5: 単 価 | AG5: 金 額 | AN5: 備 考
C7: USBメモリー(取説・設定表・レンズ清掃方法 など) | U7: 1 | Y7: 一式 | AG7: =IF(U7="",1*AB7,U7*AB7) -> 0
C8: 溶接ノズル AS-12 | U8: 1 | Y8: 個 | AG8: =IF(U8="",1*AB8,U8*AB8) -> 0
C9: 溶接ノズル BS-16 | U9: 1 | Y9: 個 | AG9: =IF(U9="",1*AB9,U9*AB9) -> 0
C10: 溶接ノズル CS-12 | U10: 1 | Y10: 個 | AG10: =IF(U10="",1*AB10,U10*AB10) -> 0
C11: 溶接ノズル FS-16 | U11: 1 | Y11: 個 | AG11: =IF(U11="",1*AB11,U11*AB11) -> 0
C12: 溶接ノズル Ｃタイプ | U12: 1 | Y12: 個 | AG12: =IF(U12="",1*AB12,U12*AB12) -> 0
C13: 切断用ノズル | U13: 1 | Y13: 個 | AG13: =IF(U13="",1*AB13,U13*AB13) -> 0
C14: ワイヤーノズル Φ1.0 | U14: 1 | Y14: 個 | AG14: =IF(U14="",1*AB14,U14*AB14) -> 0
C15: ワイヤーノズル Φ1.2 | U15: 1 | Y15: 個 | AG15: =IF(U15="",1*AB15,U15*AB15) -> 0
C16: ワイヤーノズル Φ1.6 | U16: 1 | Y16: 個 | AG16: =IF(U16="",1*AB16,U16*AB16) -> 0
C17: レンズクリーナー | U17: 1 | Y17: 個 | AG17: =IF(U17="",1*AB17,U17*AB17) -> 0
C18: レンズクリーナー用拭き取り棒 | U18: 7 | Y18: 個 | AG18: =IF(U18="",1*AB18,U18*AB18) -> 0
... C28: レーザーケーブル保護キャップ | U28: 1 | Y28: 個 | AG28: =IF(U28="",1*AB28,U28*AB28) -> 0
B29: FAX感熱紙(A4) | AG29: =IF(U29="",1*AB29,U29*AB29) -> 0
U30: 小 計
CS103: 単位
CS104: =見積書A4!CS104 -> 台
CS105: =見積書A4!CS105 -> 個
CS106: =見積書A4!CS106 -> 一式
CS107: =見積書A4!CS107 -> 冊
CS108: =見積書A4!CS108 -> 箱
CS109: =見積書A4!CS109 -> C/S
CS110: =見積書A4!CS110 -> SET
CS111: =見積書A4!CS111 -> 本
CS112: =見積書A4!CS112 -> 束
CS113: =見積書A4!CS113 -> 枚
CS114: =見積書A4!CS114 -> ﾊﾟｯｸ
CS115: =見積書A4!CS115 -> ｷｯﾄ
CS116: =見積書A4!CS116 -> 0
CI119: マスタパス | CM119: =見積書A4!CM119 -> C:\Documents and Settings\sato\My Documents\シンプル見積書\ | DO119: =見積書A4!$DO$119 -> マスタ 1.xls
CI120: データパス | CM120: =見積書A4!CM120 -> 0
P178: =見積書A4!P177 -> 0

Sheet 本体装備品一覧
D3: 本体装備品一覧 | AL3: No.
C5: 付 属 品 名 | U5: 数 量 | AB5: 単 価 | AG5: 金 額 | AN5: 備 考
AB7: =SUM(Y19) -> 0 | AG7: =IF(U7="",1*AB7,U7*AB7) -> 0
AG8: =IF(U8="",1*AB8,U8*AB8) -> 0
AG9: =IF(U9="",1*AB9,U9*AB9) -> 0
AG10: =IF(U10="",1*AB10,U10*AB10) -> 0
AG11: =IF(U11="",1*AB11,U11*AB11) -> 0
AG12: =IF(U12="",1*AB12,U12*AB12) -> 0
AG13: =IF(U13="",1*AB13,U13*AB13) -> 0
AG14: =IF(U14="",1*AB14,U14*AB14) -> 0
AG15: =IF(U15="",1*AB15,U15*AB15) -> 0
AG16: =IF(U16="",1*AB16,U16*AB16) -> 0
AG17: =IF(U17="",1*AB17,U17*AB17) -> 0
AG18: =IF(U18="",1*AB18,U18*AB18) -> 0
AG19: =IF(U19="",1*AB19,U19*AB19) -> 0
... AG28: =IF(U28="",1*AB28,U28*AB28) -> 0
B29: FAX感熱紙(A4) | AG29: =IF(U29="",1*AB29,U29*AB29) -> 0
U30: 小 計
CS103: 単位
CS104: =見積書A4!CS104 -> 台
CS105: =見積書A4!CS105 -> 個
CS106: =見積書A4!CS106 -> 一式
CS107: =見積書A4!CS107 -> 冊
CS108: =見積書A4!CS108 -> 箱
CS109: =見積書A4!CS109 -> C/S
CS110: =見積書A4!CS110 -> SET
CS111: =見積書A4!CS111 -> 本
CS112: =見積書A4!CS112 -> 束
CS113: =見積書A4!CS113 -> 枚
CS114: =見積書A4!CS114 -> ﾊﾟｯｸ
CS115: =見積書A4!CS115 -> ｷｯﾄ
CS116: =見積書A4!CS116 -> 0
CI119: マスタパス | CM119: =見積書A4!CM119 -> C:\Documents and Settings\sato\My Documents\シンプル見積書\ | DO119: =見積書A4!$DO$119 -> マスタ 1.xls
CI120: データパス | CM120: =見積書A4!CM120 -> 0
P178: =見積書A4!P177 -> 0
