Workbook

Sheet 出張デモ1
M2: CODE | AA2: 御 見 積 書
E3: 〒160-8511 | AL3: No. | AN3: FL2504075
D4: 東京都新宿区四谷4-1
AG6: 令和 | AI6: 7 | AL6: 年 | AM6: 4 | AO6: 月 | AP6: 7 | AR6: 日
D7: 大塚刷毛製造株式会社 | T7: 御中
D11: 受渡期日
D13: 受渡場所 | H13: 貴社指定場所 | AB13: 振込先： | AE13: 十六銀行 柳ヶ瀬支店 普通：0777577
D15: 現金支払 | I15: 末締め末現金払い | AB15: 名義： | AE15: ｶ)ﾘﾝｼｭﾝﾄﾞｳ
AB17: 担当者 | AF17: 田中 健吾
J19: =H51 -> 1953600
D20: 税込合計 | J20: =H51 -> 1953600
B22: 見積書有効期限発効後1年
B24: 品 名 | T24: 数 量 | AA24: 税別単価 | AF24: 金 額 | AM24: 備 考
B26: FL-LCW 1500w 加工デモ 日帰り ハイエース使用 | X26: 一式 | AA26: 66000 | AF26: =IF(T26="",1*AA26,T26*AA26) -> 66000 | AM26: 岐阜市内客先
B27: FL-LCW 1500w 加工デモ 一泊二日 公共交通 | X27: 一式 | AA27: 150000 | AF27: =IF(T27="",1*AA27,T27*AA27) -> 150000 | AM27: 茨城営業所内
B28: FL-LCW 1500w 加工デモ 一泊二日 公共交通 | X28: 一式 | AA28: 150000 | AF28: =IF(T28="",1*AA28,T28*AA28) -> 150000 | AM28: 横浜市内客先
B29: FL-LCW 1500w 加工デモ 日帰り ハイエース使用 | X29: 一式 | AA29: 85000 | AF29: =IF(T29="",1*AA29,T29*AA29) -> 85000 | AM29: 岡崎市内客先
B30: FL-LCW 1500w 加工デモ 一泊二日 公共交通 | X30: 一式 | AA30: 230000 | AF30: =IF(T30="",1*AA30,T30*AA30) -> 230000 | AM30: 函館市内客先
B31: FL-LCW 1500w 加工デモ 日帰り ハイエース使用 | X31: 一式 | AA31: 85000 | AF31: =IF(T31="",1*AA31,T31*AA31) -> 85000 | AM31: 四日市市内客先
B32: FL-LCW 1500w 加工デモ 一泊二日 公共交通 | X32: 一式 | AA32: 150000 | AF32: =IF(T32="",1*AA32,T32*AA32) -> 150000 | AM32: 行田市内客先
B33: FL-LCW 1500w 加工デモ 日帰り ハイエース使用 | X33: 一式 | AA33: 100000 | AF33: =IF(T33="",1*AA33,T33*AA33) -> 100000 | AM33: 大阪市内客先
B34: FL-LCW 1500w加工デモ 一泊二日 ハイエース使用 | X34: 一式 | AA34: 150000 | AF34: =IF(T34="",1*AA34,T34*AA34) -> 150000 | AM34: 千葉県内客先
B35: FL-LCW 1500w加工デモ 一泊二日 公共交通 | X35: 一式 | AA35: 180000 | AF35: =IF(T35="",1*AA35,T35*AA35) -> 180000 | AM35: 東京都内
B36: FL-LCW 1500w加工デモ 一泊二日 公共交通 | X36: 一式 | AA36: 180000 | AF36: =IF(T36="",1*AA36,T36*AA36) -> 180000 | AM36: 新潟市内
B37: FL-LCW 1500w加工デモ 二泊三日 ハイエース使用 | X37: 一式 | AA37: 250000 | AF37: =IF(T37="",1*AA37,T37*AA37) -> 250000 | AM37: 新潟市内
H50: =AA50*0.1 -> 177600 | T50: 小 計 | AA50: =SUM(AF26:AL37) -> 1776000
B51: 合計金額 | H51: =CK127+H50 -> 1953600
B52: 摘要： | E52: ４トン車、駐車代別途
B53: 加工デモ＝送料設置操作講習同日開催となります。
P68: =SUM(CK127:CQ127) -> 1776000
FB112: NO | FC112: 明細NO | FD112: 品名 | FE112: 数量 | FF112: 単位 | FG112: 単位 | FH112: 金額 | FI112: 備考
FB113: 0 | FC113: 1 | FD113: =B26 -> FL-LCW 1500w 加工デモ 日帰り ハイエース使用 | FE113: =T26 -> 0 | FF113: =X26 -> 一式 | FG113: =AA26 -> 66000 | FH113: =AF26 -> 66000 | FI113: =AM26 -> 岐阜市内客先
EM114: ON | FB114: 0 | FC114: 2 | FD114: =B27 -> FL-LCW 1500w 加工デモ 一泊二日 公共交通 | FE114: =T27 -> 0 | FF114: =X27 -> 一式 | FG114: =AA27 -> 150000 | FH114: =AF27 -> 150000 | FI114: =AM27 -> 茨城営業所内
CE115: 制御 | CI115: 総計 | CS115: 単位 | CW115: 消費税 | DD115: タイトル | DM115: ﾏｽﾀﾊﾞｯｸｱｯﾌﾟ | EM115: OFF | FB115: 0 | FC115: 3 | FD115: =B28 -> FL-LCW 1500w 加工デモ 一泊二日 公共交通 | FE115: =T28 -> 0 | FF115: =X28 -> 一式 | FG115: =AA28 -> 150000 | FH115: =AF28 -> 150000 | FI115: =AM28 -> 横浜市内客先
CE116: 3 | CI116: 0 | CK116: =AA50 -> 1776000 | CS116: 台 | CW116: 5 | CY116: ％ | DD116: 御 見 積 書 | DM116: ON | FB116: 0 | FC116: 4 | FD116: =B29 -> FL-LCW 1500w 加工デモ 日帰り ハイエース使用 | FE116: =T29 -> 0 | FF116: =X29 -> 一式 | FG116: =AA29 -> 85000 | FH116: =AF29 -> 85000 | FI116: =AM29 -> 岡崎市内客先
CE117: =MAX(FB413:FB654) -> 0 | CI117: 1 | CK117: =IF(ISERROR(本体装備品一覧!AB30),0,本体装備品一覧!AB30) -> 0 | CS117: 個 | DD117: 納 品 書 | FB117: 0 | FC117: 5 | FD117: =#REF! -> #REF! | FE117: =T30 -> 0 | FF117: =X30 -> 一式 | FG117: =AA30 -> 230000 | FH117: =AF30 -> 230000 | FI117: =AM30 -> 函館市内客先
CE118: 1 | CI118: 2 | CK118: =IF(ISERROR(#REF!),0,#REF!) -> 0 | CS118: 一式 | CV118: 画面表示 | DD118: 納 品 書 （控） | DM118: ﾃﾞｰﾀ保存ｼｰﾄ | FB118: 0 | FC118: 6 | FD118: =#REF! -> #REF! | FE118: =T31 -> 0 | FF118: =X31 -> 一式 | FG118: =AA31 -> 85000 | FH118: =AF31 -> 85000 | FI118: =AM31 -> 四日市市内客先
CE119: 0 | CI119: 3 | CK119: =IF(ISERROR(#REF!),0,#REF!) -> 0 | CS119: 冊 | CV119: ① | CW119: 100 | CZ119: ％ | DD119: 請 求 書 | DM119: データ保存 1.xls | FB119: 0 | FC119: 7 | FD119: =#REF! -> #REF! | FE119: =T32 -> 0 | FF119: =X32 -> 一式 | FG119: =AA32 -> 150000 | FH119: =AF32 -> 150000 | FI119: =AM32 -> 行田市内客先
CE120: 敬称 | CI120: 4 | CS120: 箱 | CV120: ② | CW120: 80 | CZ120: ％ | DD120: 請 求 書 （控） | DM120: 鑑 | FB120: 0 | FC120: 8 | FD120: =B31 -> FL-LCW 1500w 加工デモ 日帰り ハイエース使用 | FE120: =T33 -> 0 | FF120: =X33 -> 一式 | FG120: =AA33 -> 100000 | FH120: =AF33 -> 100000 | FI120: =AM33 -> 大阪市内客先
CE121: 御中 | CI121: 5 | CS121: C/S | DM121: 明細 | FB121: 0 | FC121: 9 | FD121: =B34 -> FL-LCW 1500w加工デモ 一泊二日 ハイエース使用 | FE121: =T34 -> 0 | FF121: =X34 -> 一式 | FG121: =AA34 -> 150000 | FH121: =AF34 -> 150000 | FI121: =AM34 -> 千葉県内客先
...

Sheet 出張デモ2
M2: CODE | AA2: 御 見 積 書
E3: 〒160-8511 | AL3: No. | AN3: FL2504075
D4: 東京都新宿区四谷4-1
AG6: 令和 | AI6: 7 | AL6: 年 | AM6: 6 | AO6: 月 | AP6: 17 | AR6: 日
D7: 大塚刷毛製造株式会社 | T7: 御中
D11: 受渡期日
D13: 受渡場所 | H13: 貴社指定場所 | AB13: 振込先： | AE13: 十六銀行 柳ヶ瀬支店 普通：0777577
D15: 現金支払 | I15: 末締め末現金払い | AB15: 名義： | AE15: ｶ)ﾘﾝｼｭﾝﾄﾞｳ
AB17: 担当者 | AF17: 田中 健吾
J19: =H51 -> 1358500
D20: 税込合計 | J20: =H51 -> 1358500
B22: 見積書有効期限発効後1年
B24: 品 名 | T24: 数 量 | AA24: 税別単価 | AF24: 金 額 | AM24: 備 考
B26: FL-LCW 1500w搬入講習費二泊三日 社用車 | X26: 一式 | AA26: 270000 | AF26: =IF(T26="",1*AA26,T26*AA26) -> 270000 | AM26: 福島県内
B27: FL-LCW 1500w搬入講習費一泊二日 社用車 | X27: 一式 | AA27: 150000 | AF27: =IF(T27="",1*AA27,T27*AA27) -> 150000 | AM27: 長野県伊那市
B28: FL-LCW 1500w搬入講習費一泊二日 公共 | X28: 一式 | AA28: 150000 | AF28: =IF(T28="",1*AA28,T28*AA28) -> 150000 | AM28: 仙台市
B29: FL-LCW1500wデモ機持参講習社用車使用日帰平日 | X29: 一式 | AA29: 100000 | AF29: =IF(T29="",1*AA29,T29*AA29) -> 100000 | AM29: 名古屋支店
B30: FL-LCW1500wデモ機持参講習社用車使用日帰平日 | X30: 一式 | AA30: 120000 | AF30: =IF(T30="",1*AA30,T30*AA30) -> 120000 | AM30: 高山市組合向け
B31: FL-LCW1500wデモ機持参講習社用車使用日帰土日 | X31: 一式 | AA31: 125000 | AF31: =IF(T31="",1*AA31,T31*AA31) -> 125000 | AM31: 名古屋支店
B32: FL-LCW1500wデモ機持参講習社用車使用日帰土日 | X32: 一式 | AA32: 145000 | AF32: =IF(T32="",1*AA32,T32*AA32) -> 145000 | AM32: 高山市組合向け
B33: FL-LCW1500w 新品購入持参 一泊二日 社用車 | X33: 一式 | AA33: 150000 | AF33: =IF(T33="",1*AA33,T33*AA33) -> 150000 | AM33: 石川県金沢市
X34: 一式 | AF34: =IF(T34="",1*AA34,T34*AA34) -> 0
X35: 一式 | AF35: =IF(T35="",1*AA35,T35*AA35) -> 0
X36: 一式 | AF36: =IF(T36="",1*AA36,T36*AA36) -> 0
B37: 休日割増 土日祝 | X37: 一式 | AA37: 25000 | AF37: =IF(T37="",1*AA37,T37*AA37) -> 25000
H50: =AA50*0.1 -> 123500 | T50: 小 計 | AA50: =SUM(AF26:AL37) -> 1235000
B51: 合計金額 | H51: =CK127+H50 -> 1358500
B52: 摘要： | E52: ４トン車、駐車代別途
B53: 加工デモ＝送料設置操作講習同日開催となります。
P68: =SUM(CK127:CQ127) -> 1235000
FB112: NO | FC112: 明細NO | FD112: 品名 | FE112: 数量 | FF112: 単位 | FG112: 単位 | FH112: 金額 | FI112: 備考
FB113: 0 | FC113: 1 | FD113: =B26 -> FL-LCW 1500w搬入講習費二泊三日 社用車 | FE113: =T26 -> 0 | FF113: =X26 -> 一式 | FG113: =AA26 -> 270000 | FH113: =AF26 -> 270000 | FI113: =AM26 -> 福島県内
EM114: ON | FB114: 0 | FC114: 2 | FD114: =B27 -> FL-LCW 1500w搬入講習費一泊二日 社用車 | FE114: =T27 -> 0 | FF114: =X27 -> 一式 | FG114: =AA27 -> 150000 | FH114: =AF27 -> 150000 | FI114: =AM27 -> 長野県伊那市
CE115: 制御 | CI115: 総計 | CS115: 単位 | CW115: 消費税 | DD115: タイトル | DM115: ﾏｽﾀﾊﾞｯｸｱｯﾌﾟ | EM115: OFF | FB115: 0 | FC115: 3 | FD115: =B28 -> FL-LCW 1500w搬入講習費一泊二日 公共 | FE115: =T28 -> 0 | FF115: =X28 -> 一式 | FG115: =AA28 -> 150000 | FH115: =AF28 -> 150000 | FI115: =AM28 -> 仙台市
CE116: 3 | CI116: 0 | CK116: =AA50 -> 1235000 | CS116: 台 | CW116: 5 | CY116: ％ | DD116: 御 見 積 書 | DM116: ON | FB116: 0 | FC116: 4 | FD116: =B29 -> FL-LCW1500wデモ機持参講習社用車使用日帰平日 | FE116: =T29 -> 0 | FF116: =X29 -> 一式 | FG116: =AA29 -> 100000 | FH116: =AF29 -> 100000 | FI116: =AM29 -> 名古屋支店
CE117: =MAX(FB413:FB654) -> 0 | CI117: 1 | CK117: =IF(ISERROR(本体装備品一覧!AB30),0,本体装備品一覧!AB30) -> 0 | CS117: 個 | DD117: 納 品 書 | FB117: 0 | FC117: 5 | FD117: =#REF! -> #REF! | FE117: =T30 -> 0 | FF117: =X30 -> 一式 | FG117: =AA30 -> 120000 | FH117: =AF30 -> 120000 | FI117: =AM30 -> 高山市組合向け
CE118: 1 | CI118: 2 | CK118: =IF(ISERROR(#REF!),0,#REF!) -> 0 | CS118: 一式 | CV118: 画面表示 | DD118: 納 品 書 （控） | DM118: ﾃﾞｰﾀ保存ｼｰﾄ | FB118: 0 | FC118: 6 | FD118: =#REF! -> #REF! | FE118: =T31 -> 0 | FF118: =X31 -> 一式 | FG118: =AA31 -> 125000 | FH118: =AF31 -> 125000 | FI118: =AM31 -> 名古屋支店
CE119: 0 | CI119: 3 | CK119: =IF(ISERROR(#REF!),0,#REF!) -> 0 | CS119: 冊 | CV119: ① | CW119: 100 | CZ119: ％ | DD119: 請 求 書 | DM119: データ保存 1.xls | FB119: 0 | FC119: 7 | FD119: =#REF! -> #REF! | FE119: =T32 -> 0 | FF119: =X32 -> 一式 | FG119: =AA32 -> 145000 | FH119: =AF32 -> 145000 | FI119: =AM32 -> 高山市組合向け
CE120: 敬称 | CI120: 4 | CS120: 箱 | CV120: ② | CW120: 80 | CZ120: ％ | DD120: 請 求 書 （控） | DM120: 鑑 | FB120: 0 | FC120: 8 | FD120: =B31 -> FL-LCW1500wデモ機持参講習社用車使用日帰土日 | FE120: =T33 -> 0 | FF120: =X33 -> 一式 | FG120: =AA33 -> 150000 | FH120: =AF33 -> 150000 | FI120: =AM33 -> 石川県金沢市
CE121: 御中 | CI121: 5 | CS121: C/S | DM121: 明細 | FB121: 0 | FC121: 9 | FD121: =B34 -> 0 | FE121: =T34 -> 0 | FF121: =X34 -> 一式 | FG121: =AA34 -> 0 | FH121: =AF34 -> 0 | FI121: =AM34 -> 0
...

Sheet 別紙購入おすすめ品
D3: 別紙購入おすすめ品一覧 | AL3: No.
C5: 付 属 品 名 | U5: 数 量 | AB5: 単 価 | AG5: 金 額 | AN5: 備 考
C7: 反射レンズレンズ＋ステー | U7: 1 | Y7: 枚 | AB7: 13200 | AG7: =IF(U7="",1*AB7,U7*AB7) -> 13200
C8: コリメーターレンズ | U8: 1 | Y8: 枚 | AB8: 10340 | AG8: =IF(U8="",1*AB8,U8*AB8) -> 10340
C9: 溶接・切断用焦点レンズ【ケース付き】 | U9: 1 | Y9: 枚 | AB9: 18400 | AG9: =IF(U9="",1*AB9,U9*AB9) -> 18400
C10: 洗浄用焦点レンズ【ケース付き】 | U10: 1 | Y10: 枚 | AB10: 18400 | AG10: =IF(U10="",1*AB10,U10*AB10) -> 18400
C11: シールリング ※シールリングのみ | U11: 1 | Y11: 枚 | AB11: 3960 | AG11: =IF(U11="",1*AB11,U11*AB11) -> 3960
C12: 溶接・切断用 保護レンズ | U12: 10 | Y12: 枚 | AB12: 1200 | AG12: =IF(U12="",1*AB12,U12*AB12) -> 12000
AG13: =IF(U13="",1*AB13,U13*AB13) -> 0
AG14: =IF(U14="",1*AB14,U14*AB14) -> 0
AG15: =IF(U15="",1*AB15,U15*AB15) -> 0
AG16: =IF(U16="",1*AB16,U16*AB16) -> 0
AG17: =IF(U17="",1*AB17,U17*AB17) -> 0
AG18: =IF(U18="",1*AB18,U18*AB18) -> 0
AG19: =IF(U19="",1*AB19,U19*AB19) -> 0
AG20: =IF(U20="",1*AB20,U20*AB20) -> 0
AG21: =IF(U21="",1*AB21,U21*AB21) -> 0
AG22: =IF(U22="",1*AB22,U22*AB22) -> 0
AG23: =IF(U23="",1*AB23,U23*AB23) -> 0
AG24: =IF(U24="",1*AB24,U24*AB24) -> 0
... AG28: =IF(U28="",1*AB28,U28*AB28) -> 0
B29: FAX感熱紙(A4) | AG29: =IF(U29="",1*AB29,U29*AB29) -> 0
U30: 小 計 | AB30: =SUM(AG7:AG29) -> 76300
CS103: 単位
CS104: =出張デモ1!CS116 -> 台
CS105: =出張デモ1!CS117 -> 個
CS106: =出張デモ1!CS118 -> 一式
CS107: =出張デモ1!CS119 -> 冊
CS108: =出張デモ1!CS120 -> 箱
CS109: =出張デモ1!CS121 -> C/S
CS110: =出張デモ1!CS122 -> SET
CS111: =出張デモ1!CS123 -> 本
CS112: =出張デモ1!CS124 -> 束
CS113: =出張デモ1!CS125 -> 枚
CS114: =出張デモ1!CS126 -> ﾊﾟｯｸ
CS115: =出張デモ1!CS127 -> ｷｯﾄ
CS116: =出張デモ1!CS128 -> 0
CI119: マスタパス | CM119: =出張デモ1!CM131 -> C:\Documents and Settings\sato\My Documents\シンプル見積書\ | DO119: =出張デモ1!$DO$131 -> マスタ 1.xls
CI120: データパス | CM120: =出張デモ1!CM132 -> 0
P178: =出張デモ1!P189 -> 0

Sheet USBフラッシュメモリ内一覧
D3: USBフラッシュメモリ内一覧 | AL3: No.
C5: 付 属 品 名 | U5: 数 量 | AB5: 単 価 | AG5: 金 額 | AN5: 備 考
C7: User Manual_FL_LCW-3000W Ver.2.0 （取扱 説明書) | U7: 1 | Y7: SET | AG7: =IF(U7="",1*AB7,U7*AB7) -> 0
C8: 焦点レンズの清掃・交換 | U8: 1 | Y8: SET | AG8: =IF(U8="",1*AB8,U8*AB8) -> 0
C9: 保護レンズの清掃・交換 | U9: 1 | Y9: SET
C10: 溶接の設定出し | U10: 1 | Y10: SET | AG10: =IF(U10="",1*AB10,U10*AB10) -> 0
C11: LCW全機種設定表 | U11: 1 | Y11: SET | AG11: =IF(U11="",1*AB11,U11*AB11) -> 0
C12: 3000W設定表 | U12: 1 | Y12: SET | AG12: =IF(U12="",1*AB12,U12*AB12) -> 0
AG13: =IF(U13="",1*AB13,U13*AB13) -> 0
AG14: =IF(U14="",1*AB14,U14*AB14) -> 0
AG15: =IF(U15="",1*AB15,U15*AB15) -> 0
AG16: =IF(U16="",1*AB16,U16*AB16) -> 0
AG17: =IF(U17="",1*AB17,U17*AB17) -> 0
AG18: =IF(U18="",1*AB18,U18*AB18) -> 0
AG19: =IF(U19="",1*AB19,U19*AB19) -> 0
AG20: =IF(U20="",1*AB20,U20*AB20) -> 0
AG21: =IF(U21="",1*AB21,U21*AB21) -> 0
AG22: =IF(U22="",1*AB22,U22*AB22) -> 0
AG23: =IF(U23="",1*AB23,U23*AB23) -> 0
AG24: =IF(U24="",1*AB24,U24*AB24) -> 0
... AG28: =IF(U28="",1*AB28,U28*AB28) -> 0
B29: FAX感熱紙(A4) | AG29: =IF(U29="",1*AB29,U29*AB29) -> 0
U30: 小 計
CS103: 単位
CS104: =出張デモ1!CS116 -> 台
CS105: =出張デモ1!CS117 -> 個
CS106: =出張デモ1!CS118 -> 一式
CS107: =出張デモ1!CS119 -> 冊
CS108: =出張デモ1!CS120 -> 箱
CS109: =出張デモ1!CS121 -> C/S
CS110: =出張デモ1!CS122 -> SET
CS111: =出張デモ1!CS123 -> 本
CS112: =出張デモ1!CS124 -> 束
CS113: =出張デモ1!CS125 -> 枚
CS114: =出張デモ1!CS126 -> ﾊﾟｯｸ
CS115: =出張デモ1!CS127 -> ｷｯﾄ
CS116: =出張デモ1!CS128 -> 0
CI119: マスタパス | CM119: =出張デモ1!CM131 -> C:\Documents and Settings\sato\My Documents\シンプル見積書\ | DO119: =出張デモ1!$DO$131 -> マスタ 1.xls
CI120: データパス | CM120: =出張デモ1!CM132 -> 0
P178: =出張デモ1!P189 -> 0

Sheet 工具箱内付属一覧
D3: 工具箱内付属一覧 | AL3: No.
C5: 付 属 品 名 | U5: 数 量 | AB5: 単 価 | AG5: 金 額 | AN5: 備 考
C7: USBメモリー(取説・設定表・レンズ清掃方法 など) | U7: 1 | Y7: 一式 | AG7: =IF(U7="",1*AB7,U7*AB7) -> 0
C8: 溶接ノズル AS-12 | U8: 1 | Y8: 個 | AG8: =IF(U8="",1*AB8,U8*AB8) -> 0
C9: 溶接ノズル BS-16 | U9: 1 | Y9: 個 | AG9: =IF(U9="",1*AB9,U9*AB9) -> 0
C10: 溶接ノズル CS-12 | U10: 1 | Y10: 個 | AG10: =IF(U10="",1*AB10,U10*AB10) -> 0
C11: 溶接ノズル FS-16 | U11: 1 | Y11: 個 | AG11: =IF(U11="",1*AB11,U11*AB11) -> 0
C12: 溶接ノズル Ｃタイプ | U12: 1 | Y12: 個 | AG12: =IF(U12="",1*AB12,U12*AB12) -> 0
C13: 切断用ノズル | U13: 1 | Y13: 個 | AG13: =IF(U13="",1*AB13,U13*AB13) -> 0
C14: ワイヤーノズル Φ1.0 | U14: 1 | Y14: 個 | AG14: =IF(U14="",1*AB14,U14*AB14) -> 0
C15: ワイヤーノズル Φ1.2 | U15: 1 | Y15: 個 | AG15: =IF(U15="",1*AB15,U15*AB15) -> 0
C16: ワイヤーノズル Φ1.6 | U16: 1 | Y16: 個 | AG16: =IF(U16="",1*AB16,U16*AB16) -> 0
C17: レンズクリーナー | U17: 1 | Y17: 個 | AG17: =IF(U17="",1*AB17,U17*AB17) -> 0
C18: レンズクリーナー用拭き取り棒 | U18: 7 | Y18: 個 | AG18: =IF(U18="",1*AB18,U18*AB18) -> 0
... C28: レーザーケーブル保護キャップ | U28: 1 | Y28: 個 | AG28: =IF(U28="",1*AB28,U28*AB28) -> 0
B29: FAX感熱紙(A4) | AG29: =IF(U29="",1*AB29,U29*AB29) -> 0
U30: 小 計
CS103: 単位
CS104: =出張デモ1!CS116 -> 台
CS105: =出張デモ1!CS117 -> 個
CS106: =出張デモ1!CS118 -> 一式
CS107: =出張デモ1!CS119 -> 冊
CS108: =出張デモ1!CS120 -> 箱
CS109: =出張デモ1!CS121 -> C/S
CS110: =出張デモ1!CS122 -> SET
CS111: =出張デモ1!CS123 -> 本
CS112: =出張デモ1!CS124 -> 束
CS113: =出張デモ1!CS125 -> 枚
CS114: =出張デモ1!CS126 -> ﾊﾟｯｸ
CS115: =出張デモ1!CS127 -> ｷｯﾄ
CS116: =出張デモ1!CS128 -> 0
CI119: マスタパス | CM119: =出張デモ1!CM131 -> C:\Documents and Settings\sato\My Documents\シンプル見積書\ | DO119: =出張デモ1!$DO$131 -> マスタ 1.xls
CI120: データパス | CM120: =出張デモ1!CM132 -> 0
P178: =出張デモ1!P189 -> 0

Sheet 本体装備品一覧
D3: 本体装備品一覧 | AL3: No.
C5: 付 属 品 名 | U5: 数 量 | AB5: 単 価 | AG5: 金 額 | AN5: 備 考
AB7: =SUM(Y19) -> 0 | AG7: =IF(U7="",1*AB7,U7*AB7) -> 0
AG8: =IF(U8="",1*AB8,U8*AB8) -> 0
AG9: =IF(U9="",1*AB9,U9*AB9) -> 0
AG10: =IF(U10="",1*AB10,U10*AB10) -> 0
AG11: =IF(U11="",1*AB11,U11*AB11) -> 0
AG12: =IF(U12="",1*AB12,U12*AB12) -> 0
AG13: =IF(U13="",1*AB13,U13*AB13) -> 0
AG14: =IF(U14="",1*AB14,U14*AB14) -> 0
AG15: =IF(U15="",1*AB15,U15*AB15) -> 0
AG16: =IF(U16="",1*AB16,U16*AB16) -> 0
AG17: =IF(U17="",1*AB17,U17*AB17) -> 0
AG18: =IF(U18="",1*AB18,U18*AB18) -> 0
AG19: =IF(U19="",1*AB19,U19*AB19) -> 0
... AG28: =IF(U28="",1*AB28,U28*AB28) -> 0
B29: FAX感熱紙(A4) | AG29: =IF(U29="",1*AB29,U29*AB29) -> 0
U30: 小 計
CS103: 単位
CS104: =出張デモ1!CS116 -> 台
CS105: =出張デモ1!CS117 -> 個
CS106: =出張デモ1!CS118 -> 一式
CS107: =出張デモ1!CS119 -> 冊
CS108: =出張デモ1!CS120 -> 箱
CS109: =出張デモ1!CS121 -> C/S
CS110: =出張デモ1!CS122 -> SET
CS111: =出張デモ1!CS123 -> 本
CS112: =出張デモ1!CS124 -> 束
CS113: =出張デモ1!CS125 -> 枚
CS114: =出張デモ1!CS126 -> ﾊﾟｯｸ
CS115: =出張デモ1!CS127 -> ｷｯﾄ
CS116: =出張デモ1!CS128 -> 0
CI119: マスタパス | CM119: =出張デモ1!CM131 -> C:\Documents and Settings\sato\My Documents\シンプル見積書\ | DO119: =出張デモ1!$DO$131 -> マスタ 1.xls
CI120: データパス | CM120: =出張デモ1!CM132 -> 0
P178: =出張デモ1!P189 -> 0
